Workbook

Sheet стратегия 2 под 100 тыс (отриц)
A1: Проект | B1: Мощность проекта, м2 | D1: Этажность | E1: Срок реализации, мес | F1: 3 кв. 2022 | G1: 4 кв. 2022 | J1: 1 кв. 2023 | M1: 2 кв. 2023 | P1: 3 кв. 2023 | S1: 4 кв. 2023 | V1: 1 кв. 2024 | Y1: 2 кв. 2024 | AB1: 3 кв. 2024 | AE1: 4 кв. 2024 | AH1: 1 кв. 2025 | AK1: 2 кв. 2025 | AN1: 3 кв. 2025 | AQ1: 4 кв. 2025 | AT1: 1 кв. 2026 | AW1: 2 кв. 2026 | AZ1: 3 кв. 2026 | BC1: 4 кв. 2026 | BF1: 1 кв. 2027 | BI1: 2 кв. 2027 | BL1: 3 кв. 2027 | BO1: 4 кв. 2027
F2: 44805 | G2: 44835 | H2: 44866 | I2: 44896 | J2: 44927 | K2: 44958 | L2: 44986 | M2: 45017 | N2: 45047 | O2: 45078 | P2: 45108 | Q2: 45139 | R2: 45170 | S2: 45200 | T2: 45231 | U2: 45261 | V2: 45292 | W2: 45323 | X2: 45352 | Y2: 45383 | Z2: 45413 | AA2: 45444 | AB2: 45474 | AC2: 45505 | AD2: 45536 | AE2: 45566 | AF2: 45597 | AG2: 45627 | AH2: 45658 | AI2: 45689 | AJ2: 45717 | AK2: 45748 | AL2: 45778 | AM2: 45809 | AN2: 45839 | AO2: 45870 | AP2: 45901 | AQ2: 45931 | AR2: 45962 | AS2: 45992 | AT2: 46023 | AU2: 46054 | AV2: 46082 | AW2: 46113 | AX2: 46143 | AY2: 46174 | AZ2: 46204 | BA2: 46235 | BB2: 46266 | BC2: 46296 | BD2: 46327 | BE2: 46357 | BF2: 46388 | BG2: 46419 | BH2: 46447 | BI2: 46478 | BJ2: 46508 | BK2: 46539 | BL2: 46569 | BM2: 46600 | BN2: 46631 | BO2: 46661 | BP2: 46692 | BQ2: 46722
B3: Продаваемая площадь | C3: Общая площадь | F3: 1 | G3: 2 | H3: 3 | I3: 4 | J3: 5 | K3: 6 | L3: 7 | M3: 8 | N3: 9 | O3: 10 | P3: 11 | Q3: 12 | R3: 13 | S3: 14 | T3: 15 | U3: 16 | V3: 17 | W3: 18 | X3: 19 | Y3: 20 | Z3: 21 | AA3: 22 | AB3: 23 | AC3: 24 | AD3: 25 | AE3: 26 | AF3: 27 | AG3: 28 | AH3: 29 | AI3: 30 | AJ3: 31 | AK3: 32 | AL3: 33 | AM3: 34 | AN3: 35 | AO3: 36 | AP3: 37 | AQ3: 38 | AR3: 39 | AS3: 40 | AT3: 41 | AU3: 42 | AV3: 43 | AW3: 44 | AX3: 45 | AY3: 46 | AZ3: 47 | BA3: 48 | BB3: 49 | BC3: 50 | BD3: 51 | BE3: 52 | BF3: 53 | BG3: 54 | BH3: 55 | BI3: 53 | BJ3: 54 | BK3: 55 | BL3: 53 | BM3: 54 | BN3: 55 | BO3: 53 | BP3: 54 | BQ3: 55
A4: Доп.продажи К2, тыс.руб. | I4: =I5*I6 -> 0 | J4: =J5*J6 -> 0 | K4: =K5*K6 -> 0 | L4: =L5*L6 -> 0 | M4: =M5*M6 -> 0 | N4: =N21 -> 0 | O4: =O21 -> 0 | P4: =P21 -> 0 | Q4: =Q21 -> 0 | R4: =R21 -> 0
A5: Кедровый 2, м2 | I5: =309.6*0 -> 0 | J5: =288.50755988024*0 -> 0 | K5: =117.09*0 -> 0 | L5: =321.4*0 -> 0 | M5: =301.52*0 -> 0
A6: Кедровый 2, тыс.руб./м2 | I6: 66.106935 | J6: 61.662707 | K6: 66.090554 | L6: 65.329107 | M6: 64.8
A7: Наполнение эскроу К2, тыс.руб. | I7: =I8*I9 -> 25901.975 | J7: =J8*J9 -> 21615 | K7: =K8*K9 -> 27342.975 | L7: =L8*L9 -> 33462 | M7: =M8*M9 -> 28256.8 | N7: =N8*N9 -> 46900 | O7: =O8*O9 -> 50625 | P7: =P8*P9 -> 53430 | ... R7: =R8*R9 -> 72280
A8: Кедровый 2, м2 | F8: =F10/F12 -> 1.1373577 | I8: =719*0.55 -> 395.45 | J8: =600*0.55 -> 330 | K8: =759*0.55 -> 417.45 | L8: =900*0.55 -> 495 | M8: =760*0.55 -> 418 | N8: 700 | O8: 750 | P8: 780 | Q8: 930 | R8: 1040
A9: Кедровый 2, тыс.руб./м2 | I9: 65.5 | J9: 65.5 | K9: 65.5 | L9: 67.6 | M9: 67.6 | N9: 67 | O9: 67.5 | P9: 68.5 | Q9: 69.5 | R9: 69.5
A10: Наполнение ЭСКРОУ накопительно | F10: 265886.42 | G10: 296491.57 | H10: 318795.86 | I10: =H10+I7 -> 344697.84 | J10: =I10+J7 -> 366312.84 | K10: =J10+K7 -> 393655.81 | L10: =K10+L7 -> 427117.81 | M10: =L10+M7 -> 455374.61 | N10: =M10+N7 -> 502274.61 | O10: =N10+O7 -> 552899.61 | P10: =O10+P7 -> 606329.61 | ... R10: =Q10+R7 -> 743244.61
A11: Выборка НКЛ К2 (с дек.22 расчетно) | F11: 36485.232 | G11: 31537.208 | H11: 27893.471 | I11: 32000 | J11: 32000 | K11: 32000 | L11: 32000 | M11: 32000 | N11: 32000 | O11: 50000 | P11: 50000 | Q11: 61135.156 | R11: 61135.156
A12: Остаток ссудной задолженности | F12: 233775.55 | G12: 265312.76 | H12: 293206.23 | I12: =H12+I11 -> 325206.23 | J12: =I12+J11 -> 357206.23 | K12: =J12+K11 -> 389206.23 | L12: =K12+L11 -> 421206.23 | M12: =L12+M11 -> 453206.23 | N12: =M12+N11 -> 485206.23 | O12: =N12+O11 -> 535206.23 | P12: =O12+P11 -> 585206.23 | ... R12: =Q12+R11 -> 707476.54
A13: Ставка по эскроу, исходя из наполнения | F13: =IF(F10/F12>1.5,#REF!,IF(F10/F12>1.4,#REF!,IF(F10/F12>1.3,#REF!,IF(F10/F12>1.2,#REF!,IF(F10/F12>1.1,#REF!,IF(F10/F12>1,#REF!,IF(F10/F12<1,17.73))))))) -> #REF! | G13: =IF(G10/G12>1.5,#REF!,IF(G10/G12>1.4,#REF!,IF(G10/G12>1.3,#REF!,IF(G10/G12>1.2,#REF!,IF(G10/G12>1.1,#REF!,IF(G10/G12>1,#REF!,IF(G10/G12<1,17.73))))))) -> #REF! | H13: =IF(H10/H12>1.5,#REF!,IF(H10/H12>1.4,#REF!,IF(H10/H12>1.3,#REF!,IF(H10/H12>1.2,#REF!,IF(H10/H12>1.1,#REF!,IF(H10/H12>1,#REF!,IF(H10/H12<1,17.73))))))) -> #REF! | I13: =IF(I10/I12>1.5,#REF!,IF(I10/I12>1.4,#REF!,IF(I10/I12>1.3,#REF!,IF(I10/I12>1.2,#REF!,IF(I10/I12>1.1,#REF!,IF(I10/I12>1,#REF!,IF(I10/I12<1,17.73))))))) -> #REF! | J13: =IF(J10/J12>1.5,#REF!,IF(J10/J12>1.4,#REF!,IF(J10/J12>1.3,#REF!,IF(J10/J12>1.2,#REF!,IF(J10/J12>1.1,#REF!,IF(J10/J12>1,#REF!,IF(J10/J12<1,17.73))))))) -> #REF! | K13: =IF(K10/K12>1.5,#REF!,IF(K10/K12>1.4,#REF!,IF(K10/K12>1.3,#REF!,IF(K10/K12>1.2,#REF!,IF(K10/K12>1.1,#REF!,IF(K10/K12>1,#REF!,IF(K10/K12<1,17.73))))))) -> #REF! | L13: =IF(L10/L12>1.5,#REF!,IF(L10/L12>1.4,#REF!,IF(L10/L12>1.3,#REF!,IF(L10/L12>1.2,#REF!,IF(L10/L12>1.1,#REF!,IF(L10/L12>1,#REF!,IF(L10/L12<1,17.73))))))) -> #REF! | M13: =IF(M10/M12>1.5,#REF!,IF(M10/M12>1.4,#REF!,IF(M10/M12>1.3,#REF!,IF(M10/M12>1.2,#REF!,IF(M10/M12>1.1,#REF!,IF(M10/M12>1,#REF!,IF(M10/M12<1,17.73))))))) -> #REF! | ... R13: =IF(R10/R12>1.5,#REF!,IF(R10/R12>1.4,#REF!,IF(R10/R12>1.3,#REF!,IF(R10/R12>1.2,#REF!,IF(R10/R12>1.1,#REF!,IF(R10/R12>1,#REF!,IF(R10/R12<1,17.73))))))) -> #REF!
A14: Кедровый 1 | B14: 14439.4 | F14: РНВ
A15: Кедровый 2 | B15: 18331.74 | C15: 27707.46 | D15: 9 | E15: 26 | T15: РНВ | V15: закончить продажи (продаем по 60,875 млн в месяц в среднем)
A16: Павловск 1 | B16: 10065.54 | C16: 13453.37 | D16: 9 | E16: 24 | F16: кредит | L16: 18000 | U16: РНВ | V16: закончить продажи (продаем по 39 млн в месяц в среднем)
A17: Богучар 1 | B17: 10000 | C17: 13365.771 | D17: 9 | E17: 18 | F17: ЗУ | J17: 19000 | K17: проект (П+Р) + Благоустр (отдать на проектирование за 2 месяца) | L17: РНС - начало строительства (подготовить СП, набрать сотрудников, они должны изучить проект) | O17: кредит | AC17: РНВ | AD17: закончить продажи (продаем по 32 млн в месяц в среднем - депонирование)
A18: Муром 1 | B18: 25000 | C18: =B18*1.33 -> 33250 | D18: 9 | E18: 18 | J18: =15000+2500 -> 17500 | L18: 22000 | M18: проект (П+Р) + Благоустр (отдать на проектирование за 2 месяца) | N18: предпродажи (подготовить офис, набрать сотрудников) | O18: РНС - начало строительства (подготовить СП, набрать сотрудников, они должны изучить проект) | R18: кредит | AF18: РНВ | AG18: закончить продажи (продаем по 81 млн в месяц в среднем - депонирование)
A19: Старый Оскол | B19: 14000 | C19: =B19*1.33 -> 18620 | D19: 9 | E19: 18 | I19: 5000 | J19: 3000 | M19: 20000 | N19: проект (П+Р) + Благоустр (отдать на проектирование за 2 месяца) | O19: предпродажи (подготовить офис, набрать сотрудников) | P19: РНС - начало строительства (подготовить СП, набрать сотрудников, они должны изучить проект) | S19: кредит | AG19: РНВ | AH19: закончить продажи (продаем по 36 млн в месяц в среднем - депонирование)
A20: Павловск 2 (возможна замена локации) | B20: 18534.63 | C20: =B20*1.33 -> 24651.058 | D20: 9 | E20: 18 | F20: ЗУ | G20: ТУ | H20: проект (П+Р) + Благоустр (отдать на проектирование за 2 месяца) | I20: экспертиза | J20: предпродажи (подготовить офис, набрать сотрудников) | P20: РНС - начало строительства (подготовить СП, набрать сотрудников, они должны изучить проект) | S20: кредит | AG20: РНВ | AH20: закончить продажи (продаем по 53 млн в месяц в среднем - депонирование)
A21: Итого РАСХОДЫ, тыс.руб. | I21: =I19 -> 5000 | J21: =J19+J18+J17 -> 39500 | L21: =L18 -> 22000 | M21: =M19 -> 20000
A22: Итого | B22: =SUM(B14:B20) -> 110371.31
A23: Богучар 2 | B23: 10000 | C23: 13365.771 | D23: 9 | E23: 18 | F23: ЗУ (вместе с Б1) | G23: ТУ (вместе с Б1) | H23: проект (П+Р) + Благоустр (отдать на проектирование за 2 месяца) | I23: экспертиза | J23: предпродажи (подготовить офис, набрать сотрудников) | X23: РНС - начало строительства (подготовить СП, набрать сотрудников, они должны изучить проект) | AA23: кредит | AO23: РНВ | AP23: закончить продажи (продаем по 32 млн в месяц в среднем - депонирование)
A24: Муром 2 | B24: 25000 | C24: =C18 -> 33250 | D24: 10 | E24: 18 | I24: ЗУ | M24: проект (П+Р) + Благоустр (отдать на проектирование за 2 месяца) | N24: предпродажи (подготовить офис, набрать сотрудников) | Z24: РНС - начало строительства (подготовить СП, набрать сотрудников, они должны изучить проект) | AC24: кредит | AQ24: РНВ | AR24: закончить продажи (продаем по 81 млн в месяц в среднем - депонирование)
A25: Старый Оскол | B25: 6000 | C25: =B25*1.33 -> 7980 | D25: 9 | E25: 18 | H25: ЗУ | N25: проект (П+Р) + Благоустр (отдать на проектирование за 2 месяца) | O25: предпродажи (подготовить офис, набрать сотрудников) | P25: РНС - начало строительства (подготовить СП, набрать сотрудников, они должны изучить проект) | S25: кредит | AC25: РНС - начало строительства (подготовить СП, набрать сотрудников, они должны изучить проект) | AF25: кредит | AT25: РНВ | AU25: закончить продажи (продаем по 36 млн в месяц в среднем - депонирование)
A26: За стратегией | B26: =B25+B23+B24 -> 41000 | C26: =C25+C23+C24 -> 54595.771
J31: =B15+B16+B14 -> 42836.68 | V31: =B17+B18+B20+B19+#REF! -> #REF! | AH31: =#REF!+B22+#REF!+B23 -> #REF! | AT31: =#REF!++B22+#REF! -> #REF!
V32: =V31+J31 -> #REF! | AH32: =AH31+V32 -> #REF!
AL34: нужно 2-3 локации (если один литер 18-20 м2) | AM34: =AH31-100000 -> #REF!

Sheet 1_вариант
C1: 12_2022 | D1: 01_2023 | E1: 02_2023 | F1: 03_2023 | G1: 04_2023 | H1: 05_2023 | I1: 06_2023 | J1: 07_2023 | K1: 08_2023 | L1: 09_2023 | M1: 10_2023 | N1: 11_2023 | O1: 12_2023 | P1: 01_2024 | Q1: 02_2024 | R1: 03_2024 | S1: 04_2024 | T1: 05_2024 | U1: 06_2024 | V1: 07_2024 | W1: 08_2024 | X1: 09_2024 | Y1: 10_2024 | Z1: 11_2024 | AA1: 12_2024
A2: Доп.продажи К2, тыс.руб. | C2: =C3*C5*C6*C4 -> 0 | D2: =D3*D5*D6*D4 -> 0 | E2: =E3*E5*E6*E4 -> 0 | F2: =F3*F5*F6*F4 -> 0 | G2: =G3*G5*G6*G4 -> 0 | H2: =H3*H5*H6*H4 -> 0 | I2: =I3*I5*I6*I4 -> 0 | J2: =J3*J5*J6*J4 -> 0 | ... AA2: =AA3*AA5*AA6*AA4 -> 0
A3: Кедровый 2, м2 | B3: =SUM(список_МСА!B2:B34) -> 1452.91 | C3: =SUM(список_МСА!$B2:$B8) -> 351.02 | D3: =SUM(список_МСА!$B9:$B15) -> 284.07 | E3: =SUM(список_МСА!$B16:$B23) -> 319.2 | F3: =SUM(список_МСА!$B24:$B29) -> 257.36 | G3: =SUM(список_МСА!$B30:$B33) -> 198.92 | H3: =список_МСА!B34 -> 42.34
A4: Процент выполнения по объему продаж | C4: 0 | D4: 0 | E4: 0 | F4: 0 | G4: 0 | H4: 0 | I4: 1 | J4: 1 | K4: 1 | L4: 1 | M4: 1 | N4: 1 | O4: 1 | P4: 1 | Q4: 1 | R4: 1 | S4: 1 | T4: 1 | U4: 1 | V4: 1 | W4: 1 | X4: 1 | Y4: 1 | Z4: 1 | AA4: 1
A5: Кедровый 2, тыс.руб./м2 | C5: =SUM(список_МСА!$L2:$L8)/C3/1000 -> 64.900732 | D5: =SUM(список_МСА!$L9:$L15)/D3/1000 -> 66.128662 | E5: =SUM(список_МСА!$L16:$L23)/E3/1000 -> 65.525417 | F5: =SUM(список_МСА!$L24:$L29)/F3/1000 -> 64.491743 | G5: =SUM(список_МСА!$L33:$L230)/G3/1000 -> 31.569299 | H5: =список_МСА!H34/список_МСА!B34/1000 -> 63.3
A6: Процент выполнения по объему продаж | C6: 1 | D6: 1 | E6: 1 | F6: 1 | G6: 1 | H6: 1 | I6: 1 | J6: 1 | K6: 1 | L6: 1 | M6: 1 | N6: 1 | O6: 1 | P6: 1 | Q6: 1 | R6: 1 | S6: 1 | T6: 1 | U6: 1 | V6: 1 | W6: 1 | X6: 1 | Y6: 1 | Z6: 1 | AA6: 1
A7: Наполнение эскроу К2, тыс.руб. | C7: =C8*C10 -> #REF! | D7: =D8*D10 -> #REF! | E7: =E8*E10 -> #REF! | F7: =F8*F10 -> #REF! | G7: =G8*G10 -> #REF! | H7: =H8*H10 -> #REF! | I7: =I8*I10 -> #REF! | J7: =J8*J10 -> #REF! | ... AA7: =AA8*AA10 -> #REF!
A8: Объем продаж, м2 | B8: 18442.2 | C8: =#REF!*C9 -> #REF! | D8: =IF(($B$8-#REF!-SUM('1_вариант'!$C$8:C8)-SUM('1_вариант'!$C$3:C3))>0,#REF!,0)*D9 -> #REF! | E8: =IF(($B$8-#REF!-SUM('1_вариант'!$C$8:D8)-SUM('1_вариант'!$C$3:D3))>0,#REF!,0)*E9 -> #REF! | F8: =IF(($B$8-#REF!-SUM('1_вариант'!$C$8:E8)-SUM('1_вариант'!$C$3:E3))>0,#REF!,0)*F9 -> #REF! | G8: =IF(($B$8-#REF!-SUM('1_вариант'!$C$8:F8)-SUM('1_вариант'!$C$3:F3))>0,#REF!,0)*G9 -> #REF! | H8: =IF(($B$8-#REF!-SUM('1_вариант'!$C$8:G8)-SUM('1_вариант'!$C$3:G3))>0,#REF!,0)*H9 -> #REF! | I8: =IF(($B$8-#REF!-SUM('1_вариант'!$C$8:H8)-SUM('1_вариант'!$C$3:H3))>0,#REF!,0)*I9 -> #REF! | J8: =IF(($B$8-#REF!-SUM('1_вариант'!$C$8:I8)-SUM('1_вариант'!$C$3:I3))>0,#REF!,0)*J9 -> #REF! | K8: =IF(($B$8-#REF!-SUM('1_вариант'!$C$8:J8)-SUM('1_вариант'!$C$3:J3))>0,#REF!,0)*K9 -> #REF! | ... Q8: =IF(($B$8-#REF!-SUM('1_вариант'!$C$8:P8)-SUM('1_вариант'!$C$3:P3))>0,#REF!,0)*Q9 -> #REF! | R8: =($B$8-#REF!-SUM($C$8:$Q$8,$C$3:$R$3))*R9 -> #REF! | S8: =($B$8-#REF!-SUM('1_вариант'!$C$8:R8)-SUM($C$3:R3))*S9 -> #REF! | T8: =($B$8-#REF!-SUM('1_вариант'!$C$8:S8)-SUM($C$3:S3))*T9 -> #REF! | U8: =($B$8-#REF!-SUM('1_вариант'!$C$8:T8)-SUM($C$3:T3))*U9 -> #REF! | V8: =($B$8-#REF!-SUM('1_вариант'!$C$8:U8)-SUM($C$3:U3))*V9 -> #REF! | W8: =($B$8-#REF!-SUM('1_вариант'!$C$8:V8)-SUM($C$3:V3))*W9 -> #REF! | X8: =($B$8-#REF!-SUM('1_вариант'!$C$8:W8)-SUM($C$3:W3))*X9 -> #REF! | Y8: =($B$8-#REF!-SUM('1_вариант'!$C$8:X8)-SUM($C$3:X3))*Y9 -> #REF! | Z8: =($B$8-#REF!-SUM('1_вариант'!$C$8:Y8)-SUM($C$3:Y3))*Z9 -> #REF! | AA8: =($B$8-#REF!-SUM('1_вариант'!$C$8:Z8)-SUM($C$3:Z3))*AA9 -> #REF!
A9: Процент выполнения по объему продаж | C9: 1 | D9: 1 | E9: 1 | F9: 1 | G9: 1 | H9: 1 | I9: 1 | J9: 1 | K9: 1 | L9: 1 | M9: 1 | N9: 1 | O9: 1 | P9: 1 | Q9: 1 | R9: 1 | S9: 1 | T9: 1 | U9: 1 | V9: 1 | W9: 1 | X9: 1 | Y9: 1 | Z9: 1 | AA9: 1
A10: Цена продаж тыс.руб./м2 | C10: =#REF!*'1_вариант'!C11 -> #REF! | D10: =#REF!*'1_вариант'!D11 -> #REF! | E10: =#REF!*'1_вариант'!E11 -> #REF! | F10: =#REF!*'1_вариант'!F11 -> #REF! | G10: =#REF!*'1_вариант'!G11 -> #REF! | H10: =#REF!*'1_вариант'!H11 -> #REF! | I10: =#REF!*'1_вариант'!I11 -> #REF! | J10: =#REF!*'1_вариант'!J11 -> #REF! | ... AA10: =#REF!*'1_вариант'!AA11 -> #REF!
A11: Процент выполнения по объему продаж | C11: 1 | D11: 1 | E11: 1 | F11: 1 | G11: 1 | H11: 1 | I11: 1 | J11: 1 | K11: 1 | L11: 1 | M11: 1 | N11: 1 | O11: 1 | P11: 1 | Q11: 1 | R11: 1 | S11: 1 | T11: 1 | U11: 1 | V11: 1 | W11: 1 | X11: 1 | Y11: 1 | Z11: 1 | AA11: 1
A12: Наполнение ЭСКРОУ накопительно | C12: ='стратегия 2 под 100 тыс (отриц)'!$H$10+C7 -> #REF! | D12: =C12+D7 -> #REF! | E12: =D12+E7 -> #REF! | F12: =E12+F7 -> #REF! | G12: =F12+G7 -> #REF! | H12: =G12+H7 -> #REF! | I12: =H12+I7 -> #REF! | J12: =I12+J7 -> #REF! | K12: =J12+K7 -> #REF! | ... AA12: =Z12+AA7 -> #REF!
A13: Выборка НКЛ К2 (с дек.22 расчетно) | C13: 32000 | D13: 32000 | E13: 32000 | F13: 45000 | G13: 50000 | H13: 50000 | I13: 50000 | J13: 50000 | K13: 50000 | L13: 60000 | M13: =IF(756476.54-SUM('стратегия 2 под 100 тыс (отриц)'!$H$12,$C$13:L13)>0,(756476.54-SUM('стратегия 2 под 100 тыс (отриц)'!$H$12,$C$13:L13)),0) -> 12270.311 | N13: =IF(756476.54-SUM('стратегия 2 под 100 тыс (отриц)'!$H$12,$C$13:M13)>0,(756476.54-SUM('стратегия 2 под 100 тыс (отриц)'!$H$12,$C$13:M13)),0)/2 -> 0 | O13: =IF(756476.54-SUM('стратегия 2 под 100 тыс (отриц)'!$H$12,$C$13:N13)>0,(756476.54-SUM('стратегия 2 под 100 тыс (отриц)'!$H$12,$C$13:N13)),0)/2 -> 0 | P13: =IF(756476.54-SUM('стратегия 2 под 100 тыс (отриц)'!$H$12,$C$13:O13)>0,(756476.54-SUM('стратегия 2 под 100 тыс (отриц)'!$H$12,$C$13:O13)),0)/2 -> 0 | Q13: =IF(756476.54-SUM('стратегия 2 под 100 тыс (отриц)'!$H$12,$C$13:P13)>0,(756476.54-SUM('стратегия 2 под 100 тыс (отриц)'!$H$12,$C$13:P13)),0)/2 -> 0 | R13: =IF(756476.54-SUM('стратегия 2 под 100 тыс (отриц)'!$H$12,$C$13:Q13)>0,(756476.54-SUM('стратегия 2 под 100 тыс (отриц)'!$H$12,$C$13:Q13)),0)/2 -> 0 | S13: =IF(756476.54-SUM('стратегия 2 под 100 тыс (отриц)'!$H$12,$C$13:R13)>0,(756476.54-SUM('стратегия 2 под 100 тыс (отриц)'!$H$12,$C$13:R13)),0)/2 -> 0 | T13: =IF(756476.54-SUM('стратегия 2 под 100 тыс (отриц)'!$H$12,$C$13:S13)>0,(756476.54-SUM('стратегия 2 под 100 тыс (отриц)'!$H$12,$C$13:S13)),0)/2 -> 0 | U13: =IF(756476.54-SUM('стратегия 2 под 100 тыс (отриц)'!$H$12,$C$13:T13)>0,(756476.54-SUM('стратегия 2 под 100 тыс (отриц)'!$H$12,$C$13:T13)),0)/2 -> 0 | ... W13: =IF(756476.54-SUM('стратегия 2 под 100 тыс (отриц)'!$H$12,$C$13:V13)>0,(756476.54-SUM('стратегия 2 под 100 тыс (отриц)'!$H$12,$C$13:V13)),0)/2 -> 0
A14: Остаток ссудной задолженности | C14: ='стратегия 2 под 100 тыс (отриц)'!H12+C13 -> 325206.23 | D14: =C14+D13 -> 357206.23 | E14: =D14+E13 -> 389206.23 | F14: =E14+F13 -> 434206.23 | G14: =F14+G13 -> 484206.23 | H14: =G14+H13 -> 534206.23 | I14: =H14+I13 -> 584206.23 | J14: =I14+J13 -> 634206.23 | K14: =J14+K13 -> 684206.23 | ... M14: =L14+M13 -> 756476.54
A15: Ставка по эскроу, исходя из наполнения | C15: =IF(C$12/C$14>1.5,#REF!,IF(C$12/C$14>1.4,#REF!,IF(C$12/C$14>1.3,#REF!,IF(C$12/C$14>1.2,#REF!,IF(C$12/C$14>1.1,#REF!,IF(C$12/C$14>1,#REF!,IF(C$12/C$14<1,17.73))))))) -> #REF! | D15: =IF(D$12/D$14>1.5,#REF!,IF(D$12/D$14>1.4,#REF!,IF(D$12/D$14>1.3,#REF!,IF(D$12/D$14>1.2,#REF!,IF(D$12/D$14>1.1,#REF!,IF(D$12/D$14>1,#REF!,IF(D$12/D$14<1,17.73))))))) -> #REF! | E15: =IF(E$12/E$14>1.5,#REF!,IF(E$12/E$14>1.4,#REF!,IF(E$12/E$14>1.3,#REF!,IF(E$12/E$14>1.2,#REF!,IF(E$12/E$14>1.1,#REF!,IF(E$12/E$14>1,#REF!,IF(E$12/E$14<1,17.73))))))) -> #REF! | F15: =IF(F$12/F$14>1.5,#REF!,IF(F$12/F$14>1.4,#REF!,IF(F$12/F$14>1.3,#REF!,IF(F$12/F$14>1.2,#REF!,IF(F$12/F$14>1.1,#REF!,IF(F$12/F$14>1,#REF!,IF(F$12/F$14<1,17.73))))))) -> #REF! | G15: =IF(G$12/G$14>1.5,#REF!,IF(G$12/G$14>1.4,#REF!,IF(G$12/G$14>1.3,#REF!,IF(G$12/G$14>1.2,#REF!,IF(G$12/G$14>1.1,#REF!,IF(G$12/G$14>1,#REF!,IF(G$12/G$14<1,17.73))))))) -> #REF! | H15: =IF(H$12/H$14>1.5,#REF!,IF(H$12/H$14>1.4,#REF!,IF(H$12/H$14>1.3,#REF!,IF(H$12/H$14>1.2,#REF!,IF(H$12/H$14>1.1,#REF!,IF(H$12/H$14>1,#REF!,IF(H$12/H$14<1,17.73))))))) -> #REF! | I15: =IF(I$12/I$14>1.5,#REF!,IF(I$12/I$14>1.4,#REF!,IF(I$12/I$14>1.3,#REF!,IF(I$12/I$14>1.2,#REF!,IF(I$12/I$14>1.1,#REF!,IF(I$12/I$14>1,#REF!,IF(I$12/I$14<1,17.73))))))) -> #REF! | J15: =IF(J$12/J$14>1.5,#REF!,IF(J$12/J$14>1.4,#REF!,IF(J$12/J$14>1.3,#REF!,IF(J$12/J$14>1.2,#REF!,IF(J$12/J$14>1.1,#REF!,IF(J$12/J$14>1,#REF!,IF(J$12/J$14<1,17.73))))))) -> #REF! | ... M15: =IF(M$12/M$14>1.5,#REF!,IF(M$12/M$14>1.4,#REF!,IF(M$12/M$14>1.3,#REF!,IF(M$12/M$14>1.2,#REF!,IF(M$12/M$14>1.1,#REF!,IF(M$12/M$14>1,#REF!,IF(M$12/M$14<1,17.73))))))) -> #REF!
A16: доходность, руб./м2 | B16: =(AA12-#REF!/1000-#REF!/1000)/B8 -> #REF! | C16: =($AA$12-#REF!/1000-#REF!/1000)/'1_вариант'!$B$8 -> #REF! | D16: =($AA$12-#REF!/1000-#REF!/1000)/'1_вариант'!$B$8 -> #REF! | E16: =($AA$12-#REF!/1000-#REF!/1000)/'1_вариант'!$B$8 -> #REF! | F16: =($AA$12-#REF!/1000-#REF!/1000)/'1_вариант'!$B$8 -> #REF! | G16: =($AA$12-#REF!/1000-#REF!/1000)/'1_вариант'!$B$8 -> #REF! | H16: =($AA$12-#REF!/1000-#REF!/1000)/'1_вариант'!$B$8 -> #REF! | I16: =($AA$12-#REF!/1000-#REF!/1000)/'1_вариант'!$B$8 -> #REF! | J16: =($AA$12-#REF!/1000-#REF!/1000)/'1_вариант'!$B$8 -> #REF! | ... AA16: =($AA$12-#REF!/1000-#REF!/1000)/'1_вариант'!$B$8 -> #REF!
A17: Богучар 1 | D17: 19000
A18: Муром 1 | D18: 17500 | F18: 22000
A19: Старый Оскол | C19: =4442.9748+370.2479 -> 4813.2227 | D19: 3000 | E19: =4442974.8/1000 -> 4442.9748 | G19: 20000
A20: Павловск 2 (возможна замена локации)
A21: Итого потребность в ДС | C21: =SUM(C17:C20) -> 4813.2227 | D21: =SUM(D17:D20) -> 39500 | E21: =SUM(E17:E20) -> 4442.9748 | F21: =SUM(F17:F20) -> 22000 | G21: =SUM(G17:G20) -> 20000 | H21: =SUM(H17:H20) -> 0 | I21: =SUM(I17:I20) -> 0 | J21: =SUM(J17:J20) -> 0 | ... AA21: =SUM(AA17:AA20) -> 0
A22: ИзбытокДС(+)/ДефицитДС(-) | B22: (доп.продажи) | D22: =C22+D2-D21 -> -39500 | E22: =D22+E2-E21 -> -43942.975 | F22: =E22+F2-F21 -> -65942.975 | G22: =F22+G2-G21 -> -85942.975 | H22: =G22+H2-H21 -> -85942.975 | I22: =H22+I2-I21 -> -85942.975 | J22: =I22+J2-J21 -> -85942.975 | K22: =J22+K2-K21 -> -85942.975 | ... AA22: =Z22+AA2-AA21 -> -85942.975
A23: Покрытие потребности за счет НКЛ | B23: НКЛ К2 | C23: =C19 -> 4813.2227 | D23: =IF(D22<0,-D22,0) -> 39500 | E23: =IF(E22<0,-E22,0) -> 43942.975 | F23: =IF(F22<0,-F22,0) -> 65942.975 | G23: =IF(G22<0,-G22,0) -> 85942.975 | H23: =IF(H22<0,-H22,0) -> 85942.975 | I23: =IF(I22<0,-I22,0) -> 85942.975 | J23: =IF(J22<0,-J22,0) -> 85942.975 | K23: =IF(K22<0,-K22,0) -> 85942.975 | ... AA23: =IF(AA22<0,-AA22,0) -> 85942.975
A24: !Ставка по эскроу (доп.вывод на инвестиции) | C24: =IF(C$12/(C$14+C21)>1.5,#REF!,IF(C$12/(C$14+C21)>1.4,#REF!,IF(C$12/(C$14+C21)>1.3,#REF!,IF(C$12/(C$14+C21)>1.2,#REF!,IF(C$12/(C$14+C21)>1.1,#REF!,IF(C$12/(C$14+C21)>1,#REF!,IF(C$12/(C$14+C21)<1,17.73))))))) -> #REF! | D24: =IF(D$12/(D$14+D21)>1.5,#REF!,IF(D$12/(D$14+D21)>1.4,#REF!,IF(D$12/(D$14+D21)>1.3,#REF!,IF(D$12/(D$14+D21)>1.2,#REF!,IF(D$12/(D$14+D21)>1.1,#REF!,IF(D$12/(D$14+D21)>1,#REF!,IF(D$12/(D$14+D21)<1,17.73))))))) -> #REF! | E24: =IF(E$12/(E$14+E21)>1.5,#REF!,IF(E$12/(E$14+E21)>1.4,#REF!,IF(E$12/(E$14+E21)>1.3,#REF!,IF(E$12/(E$14+E21)>1.2,#REF!,IF(E$12/(E$14+E21)>1.1,#REF!,IF(E$12/(E$14+E21)>1,#REF!,IF(E$12/(E$14+E21)<1,17.73))))))) -> #REF! | F24: =IF(F$12/(F$14+F21)>1.5,#REF!,IF(F$12/(F$14+F21)>1.4,#REF!,IF(F$12/(F$14+F21)>1.3,#REF!,IF(F$12/(F$14+F21)>1.2,#REF!,IF(F$12/(F$14+F21)>1.1,#REF!,IF(F$12/(F$14+F21)>1,#REF!,IF(F$12/(F$14+F21)<1,17.73))))))) -> #REF! | G24: =IF(G$12/(G$14+G21)>1.5,#REF!,IF(G$12/(G$14+G21)>1.4,#REF!,IF(G$12/(G$14+G21)>1.3,#REF!,IF(G$12/(G$14+G21)>1.2,#REF!,IF(G$12/(G$14+G21)>1.1,#REF!,IF(G$12/(G$14+G21)>1,#REF!,IF(G$12/(G$14+G21)<1,17.73))))))) -> #REF! | H24: =IF(H$12/(H$14+H21)>1.5,#REF!,IF(H$12/(H$14+H21)>1.4,#REF!,IF(H$12/(H$14+H21)>1.3,#REF!,IF(H$12/(H$14+H21)>1.2,#REF!,IF(H$12/(H$14+H21)>1.1,#REF!,IF(H$12/(H$14+H21)>1,#REF!,IF(H$12/(H$14+H21)<1,17.73))))))) -> #REF! | I24: =IF(I$12/(I$14+I21)>1.5,#REF!,IF(I$12/(I$14+I21)>1.4,#REF!,IF(I$12/(I$14+I21)>1.3,#REF!,IF(I$12/(I$14+I21)>1.2,#REF!,IF(I$12/(I$14+I21)>1.1,#REF!,IF(I$12/(I$14+I21)>1,#REF!,IF(I$12/(I$14+I21)<1,17.73))))))) -> #REF! | J24: =IF(J$12/(J$14+J21)>1.5,#REF!,IF(J$12/(J$14+J21)>1.4,#REF!,IF(J$12/(J$14+J21)>1.3,#REF!,IF(J$12/(J$14+J21)>1.2,#REF!,IF(J$12/(J$14+J21)>1.1,#REF!,IF(J$12/(J$14+J21)>1,#REF!,IF(J$12/(J$14+J21)<1,17.73))))))) -> #REF! | ... M24: =IF(M$12/(M$14+M21)>1.5,#REF!,IF(M$12/(M$14+M21)>1.4,#REF!,IF(M$12/(M$14+M21)>1.3,#REF!,IF(M$12/(M$14+M21)>1.2,#REF!,IF(M$12/(M$14+M21)>1.1,#REF!,IF(M$12/(M$14+M21)>1,#REF!,IF(M$12/(M$14+M21)<1,17.73))))))) -> #REF!

Sheet список_МСА
A1: № кв | B1: м2 | C1: цена, руб/м2 | D1: № дог. | E1: комн. | F1: тип
A2: 14 | B2: 47.42 | C2: 64000 | D2: 42 | E2: 2 | F2: 2ЕА | G2: Мозолин Сергей Анатольевич | H2: 3034880 | I2: 44764 | J2: 0 | K2: - | L2: 3034880 | M2: 64000 | N2: 42-К-2-1-3-14 | O2: 44764 | P2: 44769 | Q2: 3 034 880,00 - 28.07.2022 | R2: 1
A3: 17 | B3: 59.61 | C3: 67700 | D3: 43 | E3: 2 | F3: 2А | G3: Мозолин Сергей Анатольевич | H3: 4035597 | I3: 44767 | J3: 0 | K3: - | L3: 4035597 | M3: 67700 | N3: 43-К-2-1-3-17 | O3: 44767 | P3: 44769 | Q3: 4 035 597,00 - 28.07.2022 | R3: 1
A4: 21 | B4: 47.42 | C4: 64000 | D4: 44 | E4: 2 | F4: 2ЕА | G4: Мозолин Сергей Анатольевич | H4: 3034880 | I4: 44767 | J4: 0 | K4: - | L4: 3034880 | M4: 64000 | N4: 44-К-2-1-4-21 | O4: 44767 | P4: 44769 | Q4: 3 034 880,00 - 28.07.2022 | R4: 1
A5: 28 | B5: 47.32 | C5: 63300 | D5: 48 | E5: 2 | F5: 2ЕА | G5: Мозолин Сергей Анатольевич | H5: 3001686 | I5: 44767 | J5: 0 | K5: - | L5: 3001686 | M5: 63433.77 | N5: 48-К-2-1-5-28 | O5: 44767 | P5: 44769 | Q5: 3 001 686,00 - 28.07.2022 | R5: 1
A6: 31 | B6: 59.61 | C6: 67000 | D6: 47 | E6: 2 | F6: 2А | G6: Мозолин Сергей Анатольевич | H6: 3993870 | I6: 44767 | J6: 0 | K6: - | L6: 3993870 | M6: 67000 | N6: 47-К-2-1-5-31 | O6: 44767 | P6: 44769 | Q6: 3 993 870,00 - 28.07.2022 | R6: 1
A7: 32 | B7: 42.32 | C7: 63300 | D7: 49 | E7: 2 | F7: 2ЕА | G7: Мозолин Сергей Анатольевич | H7: 2678856 | I7: 44767 | J7: 0 | K7: - | L7: 2678856 | M7: 63300 | N7: 49-К-2-1-5-32 | O7: 44767 | P7: 44769 | Q7: 2 678 856,00 - 28.07.2022 | R7: 1
A8: 42 | B8: 47.32 | C8: 63300 | D8: 50 | E8: 2 | F8: 2ЕА | G8: Мозолин Сергей Анатольевич | H8: 3001686 | I8: 44767 | J8: 0 | K8: - | L8: 3001686 | M8: 63300 | N8: 50-К-2-1-7-42 | O8: 44767 | P8: 44769 | Q8: 3 001 686,00 - 28.07.2022 | R8: 1
A9: 45 | B9: 59.61 | C9: 67000 | D9: 51 | E9: 2 | F9: 2А | G9: Мозолин Сергей Анатольевич | H9: 3993870 | I9: 44767 | J9: 0 | K9: - | L9: 3993870 | M9: 67000 | N9: 51-К-2-1-7-45 | O9: 44767 | P9: 44769 | Q9: 3 993 870,00 - 28.07.2022 | R9: 1
A10: 79 | B10: 40.17 | C10: 64000 | D10: 52 | E10: 2 | F10: 2ЕА | G10: Мозолин Сергей Анатольевич | H10: 2570880 | I10: 44767 | J10: 0 | K10: - | L10: 2570880 | M10: 64000 | N10: 52-К-2-3-79 | O10: 44767 | P10: 44769 | Q10: 2 570 880,00 - 28.07.2022 | R10: 1
A11: 85 | B11: 36.03 | C11: 67500 | D11: 53 | E11: 1 | F11: 1А | G11: Мозолин Сергей Анатольевич | H11: 2432025 | I11: 44767 | J11: 0 | K11: - | L11: 2432025 | M11: 67500 | N11: 53-К-2-2-3-85 | O11: 44767 | P11: 44769 | Q11: 2 432 025,00 - 28.07.2022 | R11: 1
A12: 93 | B12: 36.03 | C12: 67500 | D12: 54 | E12: 1 | F12: 1А | G12: Мозолин Сергей Анатольевич | H12: 2432025 | I12: 44767 | J12: 0 | K12: - | L12: 2432025 | M12: 67500 | N12: 54-К-2-2-4-93 | O12: 44767 | P12: 44769 | Q12: 2 432025,00 - 28.07.2022 | R12: 1
A13: 101 | B13: 36.03 | C13: 66800 | D13: 56 | E13: 2 | F13: 2ЕА | G13: Мозолин Сергей Анатольевич | H13: 2406804 | I13: 44767 | J13: 0 | K13: - | L13: 2406804 | M13: 66800 | N13: 56-К-2-2-5-101 | O13: 44767 | P13: 44774 | Q13: 2 406 804,00 - 02.08.2022 | R13: 1
... A34: 316 | B34: 42.34 | C34: 63300 | D34: 46 | E34: 2 | F34: 2ЕА | G34: Мозолин Сергей Анатольевич | H34: 2680122 | I34: 44767 | J34: 0 | K34: - | L34: 2680122 | M34: 63300 | N34: 46-К-2-6-5-316 | O34: 44767 | P34: 44769 | Q34: 2 680 122,00 - 28.07.2022 | R34: 1

Sheet Стратегия 23 - 27
A1: Мастер - карта стратегического развития
A3: № | B3: Проект | C3: Текущий статус | D3: Кол-во секций | E3: Продаваемая площадь (М2) | F3: Срок реализации, мес | G3: 45200 | H3: 45231 | I3: 45261 | J3: 2023 | K3: 45292 | L3: 45323 | M3: 45352 | N3: 45383 | O3: 45413 | P3: 45444 | Q3: 45474 | R3: 45505 | S3: 45536 | T3: 45566 | U3: 45597 | V3: 45627 | W3: 2024 | X3: 45658 | Y3: 45689 | Z3: 45717 | AA3: 45748 | AB3: 45778 | AC3: 45809 | AD3: 45839 | AE3: 45870 | AF3: 45901 | AG3: 45931 | AH3: 45962 | AI3: 45992 | AJ3: 2025 | AK3: 46023 | AL3: 46054 | AM3: 46082 | AN3: 46113 | AO3: 46143 | AP3: 46174 | AQ3: 46204 | AR3: 46235 | AS3: 46266 | AT3: 46296 | AU3: 46327 | AV3: 46357 | AW3: 2026 | AX3: 46388 | AY3: 46419 | AZ3: 46447 | BA3: 46478 | BB3: 46508 | BC3: 46539 | BD3: 46569 | BE3: 46600 | BF3: 46631 | BG3: 46661 | BH3: 46692 | BI3: 46722 | BJ3: 2027 | BK3: 46753 | BL3: 46784 | BM3: 46813 | BN3: 46844 | BO3: 46874 | BP3: 46905 | BQ3: 46935 | BR3: 46966 | BS3: 46997 | BT3: 47027 | BU3: 47058 | BV3: 47088 | BW3: 2028 | BX3: 47119 | BY3: 47150 | BZ3: 47178 | CA3: 47209 | CB3: 47239 | CC3: 47270 | CD3: 47300 | CE3: 47331 | CF3: 47362 | CG3: 47392 | CH3: 47423 | CI3: 47453 | CJ3: 2029
G4: накопительно с 2021 года | J4: =J6+25629+1062 -> 45188 | K4: накопительно с 2021 года | W4: =J4+W6 -> 55406 | X4: накопительно с 2021 года | AJ4: =W4+AJ6 -> 83537 | AK4: накопительно с 2021 года | AW4: =AJ4+AW6 -> 121008.24 | AX4: накопительно с 2021 года | BJ4: =AW4+BJ6 -> 171358.7 | BK4: накопительно с 2021 года | BW4: =BJ4+BW6 -> 286260.68 | BX4: накопительно с 2021 года | CJ4: =BW4+CJ6 -> 351481.4
G6: всего за 2023 год | J6: =J7+J9 -> 18497 | K6: всего за 2024 год | W6: =SUM(W7:W86) -> 10218 | X6: всего за 2025 год | AJ6: =SUM(AJ7:AJ86) -> 28131 | AK6: всего за 2026 год | AW6: =SUM(AW7:AW86) -> 37471.24 | AX6: всего за 2027 год | BJ6: =SUM(BJ7:BJ86) -> 50350.46 | BK6: всего за 2028 год | BW6: =SUM(BW7:BW86) -> 114901.98 | BX6: всего за 2029 год | CJ6: =SUM(CJ7:CJ86) -> 65220.72
A7: 1 | B7: Кедровый №2 | C7: Завершен | D7: 6 | E7: 18497 | F7: =COUNTA(K7:V7,X7:AI7,AK7:AV7,AX7:BI7,BK7:BV7,BX7:CI7) -> 0 | G7: 1 | H7: 1 | I7: 1 | J7: =E7 -> 18497 | W7: =IF(K7="РНВ",$E7,IF(L7="РНВ",$E7,IF(M7="РНВ",$E7,IF(N7="РНВ",$E7,IF(O7="РНВ",$E7,IF(P7="РНВ",$E7,IF(Q7="РНВ",$E7,IF(R7="РНВ",$E7,IF(S7="РНВ",$E7,IF(T7="РНВ",$E7,IF(U7="РНВ",$E7,IF(V7="РНВ",$E7,0)))))))))))) -> 0 | AJ7: =IF(X7="РНВ",$E7,IF(Y7="РНВ",$E7,IF(Z7="РНВ",$E7,IF(AA7="РНВ",$E7,IF(AB7="РНВ",$E7,IF(AC7="РНВ",$E7,IF(AD7="РНВ",$E7,IF(AE7="РНВ",$E7,IF(AF7="РНВ",$E7,IF(AG7="РНВ",$E7,IF(AH7="РНВ",$E7,IF(AI7="РНВ",$E7,0)))))))))))) -> 0 | AW7: =IF(AK7="РНВ",$E7,IF(AL7="РНВ",$E7,IF(AM7="РНВ",$E7,IF(AN7="РНВ",$E7,IF(AO7="РНВ",$E7,IF(AP7="РНВ",$E7,IF(AQ7="РНВ",$E7,IF(AR7="РНВ",$E7,IF(AS7="РНВ",$E7,IF(AT7="РНВ",$E7,IF(AU7="РНВ",$E7,IF(AV7="РНВ",$E7,0)))))))))))) -> 0 | BJ7: =IF(AX7="РНВ",$E7,IF(AY7="РНВ",$E7,IF(AZ7="РНВ",$E7,IF(BA7="РНВ",$E7,IF(BB7="РНВ",$E7,IF(BC7="РНВ",$E7,IF(BD7="РНВ",$E7,IF(BE7="РНВ",$E7,IF(BF7="РНВ",$E7,IF(BG7="РНВ",$E7,IF(BH7="РНВ",$E7,IF(BI7="РНВ",$E7,0)))))))))))) -> 0 | BW7: =IF(BK7="РНВ",$E7,IF(BL7="РНВ",$E7,IF(BM7="РНВ",$E7,IF(BN7="РНВ",$E7,IF(BO7="РНВ",$E7,IF(BP7="РНВ",$E7,IF(BQ7="РНВ",$E7,IF(BR7="РНВ",$E7,IF(BS7="РНВ",$E7,IF(BT7="РНВ",$E7,IF(BU7="РНВ",$E7,IF(BV7="РНВ",$E7,0)))))))))))) -> 0 | CJ7: =IF(BX7="РНВ",$E7,IF(BY7="РНВ",$E7,IF(BZ7="РНВ",$E7,IF(CA7="РНВ",$E7,IF(CB7="РНВ",$E7,IF(CC7="РНВ",$E7,IF(CD7="РНВ",$E7,IF(CE7="РНВ",$E7,IF(CF7="РНВ",$E7,IF(CG7="РНВ",$E7,IF(CH7="РНВ",$E7,IF(CI7="РНВ",$E7,0)))))))))))) -> 0
AK8: =IF(AK7>0,$E7/$F7,0) -> 0 | AL8: =IF(AL7>0,$E7/$F7,0) -> 0 | AM8: =IF(AM7>0,$E7/$F7,0) -> 0 | AN8: =IF(AN7>0,$E7/$F7,0) -> 0 | AO8: =IF(AO7>0,$E7/$F7,0) -> 0 | AP8: =IF(AP7>0,$E7/$F7,0) -> 0 | AQ8: =IF(AQ7>0,$E7/$F7,0) -> 0 | AR8: =IF(AR7>0,$E7/$F7,0) -> 0 | ... AV8: =IF(AV7>0,$E7/$F7,0) -> 0 | AX8: =IF(AX7>0,$E7/$F7,0) -> 0 | AY8: =IF(AY7>0,$E7/$F7,0) -> 0 | AZ8: =IF(AZ7>0,$E7/$F7,0) -> 0 | BA8: =IF(BA7>0,$E7/$F7,0) -> 0 | BB8: =IF(BB7>0,$E7/$F7,0) -> 0 | BC8: =IF(BC7>0,$E7/$F7,0) -> 0 | BD8: =IF(BD7>0,$E7/$F7,0) -> 0 | BE8: =IF(BE7>0,$E7/$F7,0) -> 0 | ... BI8: =IF(BI7>0,$E7/$F7,0) -> 0 | BK8: =IF(BK7>0,$E7/$F7,0) -> 0 | BL8: =IF(BL7>0,$E7/$F7,0) -> 0 | BM8: =IF(BM7>0,$E7/$F7,0) -> 0 | BN8: =IF(BN7>0,$E7/$F7,0) -> 0 | BO8: =IF(BO7>0,$E7/$F7,0) -> 0 | BP8: =IF(BP7>0,$E7/$F7,0) -> 0 | BQ8: =IF(BQ7>0,$E7/$F7,0) -> 0 | BR8: =IF(BR7>0,$E7/$F7,0) -> 0 | ... BV8: =IF(BV7>0,$E7/$F7,0) -> 0 | BX8: =IF(BX7>0,$E7/$F7,0) -> 0 | BY8: =IF(BY7>0,$E7/$F7,0) -> 0 | BZ8: =IF(BZ7>0,$E7/$F7,0) -> 0 | CA8: =IF(CA7>0,$E7/$F7,0) -> 0 | CB8: =IF(CB7>0,$E7/$F7,0) -> 0 | CC8: =IF(CC7>0,$E7/$F7,0) -> 0 | CD8: =IF(CD7>0,$E7/$F7,0) -> 0 | CE8: =IF(CE7>0,$E7/$F7,0) -> 0 | ... CI8: =IF(CI7>0,$E7/$F7,0) -> 0
A9: 2 | B9: Павловск №1 | C9: Завершен | D9: 3 | E9: 10218 | F9: =COUNTA(K9:V9,X9:AI9,AK9:AV9,AX9:BI9,BK9:BV9,BX9:CI9) -> 2 | G9: 1 | H9: 1 | I9: 1 | K9: 1 | L9: 1 | W9: =E9 -> 10218 | AJ9: =IF(X9="РНВ",$E9,IF(Y9="РНВ",$E9,IF(Z9="РНВ",$E9,IF(AA9="РНВ",$E9,IF(AB9="РНВ",$E9,IF(AC9="РНВ",$E9,IF(AD9="РНВ",$E9,IF(AE9="РНВ",$E9,IF(AF9="РНВ",$E9,IF(AG9="РНВ",$E9,IF(AH9="РНВ",$E9,IF(AI9="РНВ",$E9,0)))))))))))) -> 0 | AW9: =IF(AK9="РНВ",$E9,IF(AL9="РНВ",$E9,IF(AM9="РНВ",$E9,IF(AN9="РНВ",$E9,IF(AO9="РНВ",$E9,IF(AP9="РНВ",$E9,IF(AQ9="РНВ",$E9,IF(AR9="РНВ",$E9,IF(AS9="РНВ",$E9,IF(AT9="РНВ",$E9,IF(AU9="РНВ",$E9,IF(AV9="РНВ",$E9,0)))))))))))) -> 0 | BJ9: =IF(AX9="РНВ",$E9,IF(AY9="РНВ",$E9,IF(AZ9="РНВ",$E9,IF(BA9="РНВ",$E9,IF(BB9="РНВ",$E9,IF(BC9="РНВ",$E9,IF(BD9="РНВ",$E9,IF(BE9="РНВ",$E9,IF(BF9="РНВ",$E9,IF(BG9="РНВ",$E9,IF(BH9="РНВ",$E9,IF(BI9="РНВ",$E9,0)))))))))))) -> 0 | BW9: =IF(BK9="РНВ",$E9,IF(BL9="РНВ",$E9,IF(BM9="РНВ",$E9,IF(BN9="РНВ",$E9,IF(BO9="РНВ",$E9,IF(BP9="РНВ",$E9,IF(BQ9="РНВ",$E9,IF(BR9="РНВ",$E9,IF(BS9="РНВ",$E9,IF(BT9="РНВ",$E9,IF(BU9="РНВ",$E9,IF(BV9="РНВ",$E9,0)))))))))))) -> 0 | CJ9: =IF(BX9="РНВ",$E9,IF(BY9="РНВ",$E9,IF(BZ9="РНВ",$E9,IF(CA9="РНВ",$E9,IF(CB9="РНВ",$E9,IF(CC9="РНВ",$E9,IF(CD9="РНВ",$E9,IF(CE9="РНВ",$E9,IF(CF9="РНВ",$E9,IF(CG9="РНВ",$E9,IF(CH9="РНВ",$E9,IF(CI9="РНВ",$E9,0)))))))))))) -> 0
AK10: =IF(AK9>0,$E9/$F9,0) -> 0 | AL10: =IF(AL9>0,$E9/$F9,0) -> 0 | AM10: =IF(AM9>0,$E9/$F9,0) -> 0 | AN10: =IF(AN9>0,$E9/$F9,0) -> 0 | AO10: =IF(AO9>0,$E9/$F9,0) -> 0 | AP10: =IF(AP9>0,$E9/$F9,0) -> 0 | AQ10: =IF(AQ9>0,$E9/$F9,0) -> 0 | AR10: =IF(AR9>0,$E9/$F9,0) -> 0 | ... AV10: =IF(AV9>0,$E9/$F9,0) -> 0 | AX10: =IF(AX9>0,$E9/$F9,0) -> 0 | AY10: =IF(AY9>0,$E9/$F9,0) -> 0 | AZ10: =IF(AZ9>0,$E9/$F9,0) -> 0 | BA10: =IF(BA9>0,$E9/$F9,0) -> 0 | BB10: =IF(BB9>0,$E9/$F9,0) -> 0 | BC10: =IF(BC9>0,$E9/$F9,0) -> 0 | BD10: =IF(BD9>0,$E9/$F9,0) -> 0 | BE10: =IF(BE9>0,$E9/$F9,0) -> 0 | ... BI10: =IF(BI9>0,$E9/$F9,0) -> 0 | BK10: =IF(BK9>0,$E9/$F9,0) -> 0 | BL10: =IF(BL9>0,$E9/$F9,0) -> 0 | BM10: =IF(BM9>0,$E9/$F9,0) -> 0 | BN10: =IF(BN9>0,$E9/$F9,0) -> 0 | BO10: =IF(BO9>0,$E9/$F9,0) -> 0 | BP10: =IF(BP9>0,$E9/$F9,0) -> 0 | BQ10: =IF(BQ9>0,$E9/$F9,0) -> 0 | BR10: =IF(BR9>0,$E9/$F9,0) -> 0 | ... BV10: =IF(BV9>0,$E9/$F9,0) -> 0 | BX10: =IF(BX9>0,$E9/$F9,0) -> 0 | BY10: =IF(BY9>0,$E9/$F9,0) -> 0 | BZ10: =IF(BZ9>0,$E9/$F9,0) -> 0 | CA10: =IF(CA9>0,$E9/$F9,0) -> 0 | CB10: =IF(CB9>0,$E9/$F9,0) -> 0 | CC10: =IF(CC9>0,$E9/$F9,0) -> 0 | CD10: =IF(CD9>0,$E9/$F9,0) -> 0 | CE10: =IF(CE9>0,$E9/$F9,0) -> 0 | ... CI10: =IF(CI9>0,$E9/$F9,0) -> 0
A11: 3 | B11: Павловск №2 | C11: Завершен | D11: 6 | E11: 18352 | F11: =COUNTA(K11:V11,X11:AI11,AK11:AV11,AX11:BI11,BK11:BV11,BX11:CI11) -> 16 | G11: 1 | H11: 1 | I11: 1 | K11: 1 | L11: 1 | M11: 1 | N11: 1 | O11: 1 | P11: 1 | Q11: 1 | R11: 1 | S11: 1 | T11: 1 | U11: 1 | V11: 1 | W11: =IF(K11="РНВ",$E11,IF(L11="РНВ",$E11,IF(M11="РНВ",$E11,IF(N11="РНВ",$E11,IF(O11="РНВ",$E11,IF(P11="РНВ",$E11,IF(Q11="РНВ",$E11,IF(R11="РНВ",$E11,IF(S11="РНВ",$E11,IF(T11="РНВ",$E11,IF(U11="РНВ",$E11,IF(V11="РНВ",$E11,0)))))))))))) -> 0 | X11: 1 | Y11: 1 | Z11: 1 | AA11: РНВ | AJ11: =IF(X11="РНВ",$E11,IF(Y11="РНВ",$E11,IF(Z11="РНВ",$E11,IF(AA11="РНВ",$E11,IF(AB11="РНВ",$E11,IF(AC11="РНВ",$E11,IF(AD11="РНВ",$E11,IF(AE11="РНВ",$E11,IF(AF11="РНВ",$E11,IF(AG11="РНВ",$E11,IF(AH11="РНВ",$E11,IF(AI11="РНВ",$E11,0)))))))))))) -> 18352 | AW11: =IF(AK11="РНВ",$E11,IF(AL11="РНВ",$E11,IF(AM11="РНВ",$E11,IF(AN11="РНВ",$E11,IF(AO11="РНВ",$E11,IF(AP11="РНВ",$E11,IF(AQ11="РНВ",$E11,IF(AR11="РНВ",$E11,IF(AS11="РНВ",$E11,IF(AT11="РНВ",$E11,IF(AU11="РНВ",$E11,IF(AV11="РНВ",$E11,0)))))))))))) -> 0 | BJ11: =IF(AX11="РНВ",$E11,IF(AY11="РНВ",$E11,IF(AZ11="РНВ",$E11,IF(BA11="РНВ",$E11,IF(BB11="РНВ",$E11,IF(BC11="РНВ",$E11,IF(BD11="РНВ",$E11,IF(BE11="РНВ",$E11,IF(BF11="РНВ",$E11,IF(BG11="РНВ",$E11,IF(BH11="РНВ",$E11,IF(BI11="РНВ",$E11,0)))))))))))) -> 0 | BW11: =IF(BK11="РНВ",$E11,IF(BL11="РНВ",$E11,IF(BM11="РНВ",$E11,IF(BN11="РНВ",$E11,IF(BO11="РНВ",$E11,IF(BP11="РНВ",$E11,IF(BQ11="РНВ",$E11,IF(BR11="РНВ",$E11,IF(BS11="РНВ",$E11,IF(BT11="РНВ",$E11,IF(BU11="РНВ",$E11,IF(BV11="РНВ",$E11,0)))))))))))) -> 0 | CJ11: =IF(BX11="РНВ",$E11,IF(BY11="РНВ",$E11,IF(BZ11="РНВ",$E11,IF(CA11="РНВ",$E11,IF(CB11="РНВ",$E11,IF(CC11="РНВ",$E11,IF(CD11="РНВ",$E11,IF(CE11="РНВ",$E11,IF(CF11="РНВ",$E11,IF(CG11="РНВ",$E11,IF(CH11="РНВ",$E11,IF(CI11="РНВ",$E11,0)))))))))))) -> 0
AK12: =IF(AK11>0,$E11/$F11,0) -> 0 | AL12: =IF(AL11>0,$E11/$F11,0) -> 0 | AM12: =IF(AM11>0,$E11/$F11,0) -> 0 | AN12: =IF(AN11>0,$E11/$F11,0) -> 0 | AO12: =IF(AO11>0,$E11/$F11,0) -> 0 | AP12: =IF(AP11>0,$E11/$F11,0) -> 0 | AQ12: =IF(AQ11>0,$E11/$F11,0) -> 0 | AR12: =IF(AR11>0,$E11/$F11,0) -> 0 | ... AV12: =IF(AV11>0,$E11/$F11,0) -> 0 | AX12: =IF(AX11>0,$E11/$F11,0) -> 0 | AY12: =IF(AY11>0,$E11/$F11,0) -> 0 | AZ12: =IF(AZ11>0,$E11/$F11,0) -> 0 | BA12: =IF(BA11>0,$E11/$F11,0) -> 0 | BB12: =IF(BB11>0,$E11/$F11,0) -> 0 | BC12: =IF(BC11>0,$E11/$F11,0) -> 0 | BD12: =IF(BD11>0,$E11/$F11,0) -> 0 | BE12: =IF(BE11>0,$E11/$F11,0) -> 0 | ... BI12: =IF(BI11>0,$E11/$F11,0) -> 0 | BK12: =IF(BK11>0,$E11/$F11,0) -> 0 | BL12: =IF(BL11>0,$E11/$F11,0) -> 0 | BM12: =IF(BM11>0,$E11/$F11,0) -> 0 | BN12: =IF(BN11>0,$E11/$F11,0) -> 0 | BO12: =IF(BO11>0,$E11/$F11,0) -> 0 | BP12: =IF(BP11>0,$E11/$F11,0) -> 0 | BQ12: =IF(BQ11>0,$E11/$F11,0) -> 0 | BR12: =IF(BR11>0,$E11/$F11,0) -> 0 | ... BV12: =IF(BV11>0,$E11/$F11,0) -> 0 | BX12: =IF(BX11>0,$E11/$F11,0) -> 0 | BY12: =IF(BY11>0,$E11/$F11,0) -> 0 | BZ12: =IF(BZ11>0,$E11/$F11,0) -> 0 | CA12: =IF(CA11>0,$E11/$F11,0) -> 0 | CB12: =IF(CB11>0,$E11/$F11,0) -> 0 | CC12: =IF(CC11>0,$E11/$F11,0) -> 0 | CD12: =IF(CD11>0,$E11/$F11,0) -> 0 | CE12: =IF(CE11>0,$E11/$F11,0) -> 0 | ... CI12: =IF(CI11>0,$E11/$F11,0) -> 0
A13: 4 | B13: Богучар №1 | C13: Завершен | D13: 3 | E13: 9779 | F13: =COUNTA(K13:V13,X13:AI13,AK13:AV13,AX13:BI13,BK13:BV13,BX13:CI13) -> 20 | G13: 1 | H13: 1 | I13: 1 | K13: 1 | L13: 1 | M13: 1 | N13: 1 | O13: 1 | P13: 1 | Q13: 1 | R13: 1 | S13: 1 | T13: 1 | U13: 1 | V13: 1 | W13: =IF(K13="РНВ",$E13,IF(L13="РНВ",$E13,IF(M13="РНВ",$E13,IF(N13="РНВ",$E13,IF(O13="РНВ",$E13,IF(P13="РНВ",$E13,IF(Q13="РНВ",$E13,IF(R13="РНВ",$E13,IF(S13="РНВ",$E13,IF(T13="РНВ",$E13,IF(U13="РНВ",$E13,IF(V13="РНВ",$E13,0)))))))))))) -> 0 | X13: 1 | Y13: 1 | Z13: 1 | AA13: 1 | AB13: 1 | AC13: 1 | AD13: 1 | AE13: РНВ | AJ13: =IF(X13="РНВ",$E13,IF(Y13="РНВ",$E13,IF(Z13="РНВ",$E13,IF(AA13="РНВ",$E13,IF(AB13="РНВ",$E13,IF(AC13="РНВ",$E13,IF(AD13="РНВ",$E13,IF(AE13="РНВ",$E13,IF(AF13="РНВ",$E13,IF(AG13="РНВ",$E13,IF(AH13="РНВ",$E13,IF(AI13="РНВ",$E13,0)))))))))))) -> 9779 | AW13: =IF(AK13="РНВ",$E13,IF(AL13="РНВ",$E13,IF(AM13="РНВ",$E13,IF(AN13="РНВ",$E13,IF(AO13="РНВ",$E13,IF(AP13="РНВ",$E13,IF(AQ13="РНВ",$E13,IF(AR13="РНВ",$E13,IF(AS13="РНВ",$E13,IF(AT13="РНВ",$E13,IF(AU13="РНВ",$E13,IF(AV13="РНВ",$E13,0)))))))))))) -> 0 | BJ13: =IF(AX13="РНВ",$E13,IF(AY13="РНВ",$E13,IF(AZ13="РНВ",$E13,IF(BA13="РНВ",$E13,IF(BB13="РНВ",$E13,IF(BC13="РНВ",$E13,IF(BD13="РНВ",$E13,IF(BE13="РНВ",$E13,IF(BF13="РНВ",$E13,IF(BG13="РНВ",$E13,IF(BH13="РНВ",$E13,IF(BI13="РНВ",$E13,0)))))))))))) -> 0 | BW13: =IF(BK13="РНВ",$E13,IF(BL13="РНВ",$E13,IF(BM13="РНВ",$E13,IF(BN13="РНВ",$E13,IF(BO13="РНВ",$E13,IF(BP13="РНВ",$E13,IF(BQ13="РНВ",$E13,IF(BR13="РНВ",$E13,IF(BS13="РНВ",$E13,IF(BT13="РНВ",$E13,IF(BU13="РНВ",$E13,IF(BV13="РНВ",$E13,0)))))))))))) -> 0 | CJ13: =IF(BX13="РНВ",$E13,IF(BY13="РНВ",$E13,IF(BZ13="РНВ",$E13,IF(CA13="РНВ",$E13,IF(CB13="РНВ",$E13,IF(CC13="РНВ",$E13,IF(CD13="РНВ",$E13,IF(CE13="РНВ",$E13,IF(CF13="РНВ",$E13,IF(CG13="РНВ",$E13,IF(CH13="РНВ",$E13,IF(CI13="РНВ",$E13,0)))))))))))) -> 0
AK14: =IF(AK13>0,$E13/$F13,0) -> 0 | AL14: =IF(AL13>0,$E13/$F13,0) -> 0 | AM14: =IF(AM13>0,$E13/$F13,0) -> 0 | AN14: =IF(AN13>0,$E13/$F13,0) -> 0 | AO14: =IF(AO13>0,$E13/$F13,0) -> 0 | AP14: =IF(AP13>0,$E13/$F13,0) -> 0 | AQ14: =IF(AQ13>0,$E13/$F13,0) -> 0 | AR14: =IF(AR13>0,$E13/$F13,0) -> 0 | ... AV14: =IF(AV13>0,$E13/$F13,0) -> 0 | AX14: =IF(AX13>0,$E13/$F13,0) -> 0 | AY14: =IF(AY13>0,$E13/$F13,0) -> 0 | AZ14: =IF(AZ13>0,$E13/$F13,0) -> 0 | BA14: =IF(BA13>0,$E13/$F13,0) -> 0 | BB14: =IF(BB13>0,$E13/$F13,0) -> 0 | BC14: =IF(BC13>0,$E13/$F13,0) -> 0 | BD14: =IF(BD13>0,$E13/$F13,0) -> 0 | BE14: =IF(BE13>0,$E13/$F13,0) -> 0 | ... BI14: =IF(BI13>0,$E13/$F13,0) -> 0 | BK14: =IF(BK13>0,$E13/$F13,0) -> 0 | BL14: =IF(BL13>0,$E13/$F13,0) -> 0 | BM14: =IF(BM13>0,$E13/$F13,0) -> 0 | BN14: =IF(BN13>0,$E13/$F13,0) -> 0 | BO14: =IF(BO13>0,$E13/$F13,0) -> 0 | BP14: =IF(BP13>0,$E13/$F13,0) -> 0 | BQ14: =IF(BQ13>0,$E13/$F13,0) -> 0 | BR14: =IF(BR13>0,$E13/$F13,0) -> 0 | ... BV14: =IF(BV13>0,$E13/$F13,0) -> 0 | BX14: =IF(BX13>0,$E13/$F13,0) -> 0 | BY14: =IF(BY13>0,$E13/$F13,0) -> 0 | BZ14: =IF(BZ13>0,$E13/$F13,0) -> 0 | CA14: =IF(CA13>0,$E13/$F13,0) -> 0 | CB14: =IF(CB13>0,$E13/$F13,0) -> 0 | CC14: =IF(CC13>0,$E13/$F13,0) -> 0 | CD14: =IF(CD13>0,$E13/$F13,0) -> 0 | CE14: =IF(CE13>0,$E13/$F13,0) -> 0 | ... CI14: =IF(CI13>0,$E13/$F13,0) -> 0
A15: 5 | B15: Богучар №2 | C15: Строительство | D15: 3 | E15: 9572.31 | F15: =COUNTA(K15:V15,X15:AI15,AK15:AV15,AX15:BI15,BK15:BV15,BX15:CI15) -> 22 | W15: =IF(K15="РНВ",$E15,IF(L15="РНВ",$E15,IF(M15="РНВ",$E15,IF(N15="РНВ",$E15,IF(O15="РНВ",$E15,IF(P15="РНВ",$E15,IF(Q15="РНВ",$E15,IF(R15="РНВ",$E15,IF(S15="РНВ",$E15,IF(T15="РНВ",$E15,IF(U15="РНВ",$E15,IF(V15="РНВ",$E15,0)))))))))))) -> 0 | Z15: 1 | AA15: 1 | AB15: 1 | AC15: 1 | AD15: 1 | AE15: 1 | AF15: 1 | AG15: 1 | AH15: 1 | AI15: 1 | AJ15: =IF(X15="РНВ",$E15,IF(Y15="РНВ",$E15,IF(Z15="РНВ",$E15,IF(AA15="РНВ",$E15,IF(AB15="РНВ",$E15,IF(AC15="РНВ",$E15,IF(AD15="РНВ",$E15,IF(AE15="РНВ",$E15,IF(AF15="РНВ",$E15,IF(AG15="РНВ",$E15,IF(AH15="РНВ",$E15,IF(AI15="РНВ",$E15,0)))))))))))) -> 0 | AK15: 1 | AL15: 1 | AM15: 1 | AN15: 1 | AO15: 1 | AP15: 1 | AQ15: 1 | AR15: 1 | AS15: 1 | AT15: 1 | AU15: 1 | AV15: РНВ | AW15: =IF(AK15="РНВ",$E15,IF(AL15="РНВ",$E15,IF(AM15="РНВ",$E15,IF(AN15="РНВ",$E15,IF(AO15="РНВ",$E15,IF(AP15="РНВ",$E15,IF(AQ15="РНВ",$E15,IF(AR15="РНВ",$E15,IF(AS15="РНВ",$E15,IF(AT15="РНВ",$E15,IF(AU15="РНВ",$E15,IF(AV15="РНВ",$E15,0)))))))))))) -> 9572.31 | BJ15: =IF(AX15="РНВ",$E15,IF(AY15="РНВ",$E15,IF(AZ15="РНВ",$E15,IF(BA15="РНВ",$E15,IF(BB15="РНВ",$E15,IF(BC15="РНВ",$E15,IF(BD15="РНВ",$E15,IF(BE15="РНВ",$E15,IF(BF15="РНВ",$E15,IF(BG15="РНВ",$E15,IF(BH15="РНВ",$E15,IF(BI15="РНВ",$E15,0)))))))))))) -> 0 | BW15: =IF(BK15="РНВ",$E15,IF(BL15="РНВ",$E15,IF(BM15="РНВ",$E15,IF(BN15="РНВ",$E15,IF(BO15="РНВ",$E15,IF(BP15="РНВ",$E15,IF(BQ15="РНВ",$E15,IF(BR15="РНВ",$E15,IF(BS15="РНВ",$E15,IF(BT15="РНВ",$E15,IF(BU15="РНВ",$E15,IF(BV15="РНВ",$E15,0)))))))))))) -> 0 | CJ15: =IF(BX15="РНВ",$E15,IF(BY15="РНВ",$E15,IF(BZ15="РНВ",$E15,IF(CA15="РНВ",$E15,IF(CB15="РНВ",$E15,IF(CC15="РНВ",$E15,IF(CD15="РНВ",$E15,IF(CE15="РНВ",$E15,IF(CF15="РНВ",$E15,IF(CG15="РНВ",$E15,IF(CH15="РНВ",$E15,IF(CI15="РНВ",$E15,0)))))))))))) -> 0
AK16: =IF(AK15>0,$E15/$F15,0) -> 435.105 | AL16: =IF(AL15>0,$E15/$F15,0) -> 435.105 | AM16: =IF(AM15>0,$E15/$F15,0) -> 435.105 | AN16: =IF(AN15>0,$E15/$F15,0) -> 435.105 | AO16: =IF(AO15>0,$E15/$F15,0) -> 435.105 | AP16: =IF(AP15>0,$E15/$F15,0) -> 435.105 | AQ16: =IF(AQ15>0,$E15/$F15,0) -> 435.105 | AR16: =IF(AR15>0,$E15/$F15,0) -> 435.105 | ... AV16: =IF(AV15>0,$E15/$F15,0) -> 435.105 | AX16: =IF(AX15>0,$E15/$F15,0) -> 0 | AY16: =IF(AY15>0,$E15/$F15,0) -> 0 | AZ16: =IF(AZ15>0,$E15/$F15,0) -> 0 | BA16: =IF(BA15>0,$E15/$F15,0) -> 0 | BB16: =IF(BB15>0,$E15/$F15,0) -> 0 | BC16: =IF(BC15>0,$E15/$F15,0) -> 0 | BD16: =IF(BD15>0,$E15/$F15,0) -> 0 | BE16: =IF(BE15>0,$E15/$F15,0) -> 0 | ... BI16: =IF(BI15>0,$E15/$F15,0) -> 0 | BK16: =IF(BK15>0,$E15/$F15,0) -> 0 | BL16: =IF(BL15>0,$E15/$F15,0) -> 0 | BM16: =IF(BM15>0,$E15/$F15,0) -> 0 | BN16: =IF(BN15>0,$E15/$F15,0) -> 0 | BO16: =IF(BO15>0,$E15/$F15,0) -> 0 | BP16: =IF(BP15>0,$E15/$F15,0) -> 0 | BQ16: =IF(BQ15>0,$E15/$F15,0) -> 0 | BR16: =IF(BR15>0,$E15/$F15,0) -> 0 | ... BV16: =IF(BV15>0,$E15/$F15,0) -> 0 | BX16: =IF(BX15>0,$E15/$F15,0) -> 0 | BY16: =IF(BY15>0,$E15/$F15,0) -> 0 | BZ16: =IF(BZ15>0,$E15/$F15,0) -> 0 | CA16: =IF(CA15>0,$E15/$F15,0) -> 0 | CB16: =IF(CB15>0,$E15/$F15,0) -> 0 | CC16: =IF(CC15>0,$E15/$F15,0) -> 0 | CD16: =IF(CD15>0,$E15/$F15,0) -> 0 | CE16: =IF(CE15>0,$E15/$F15,0) -> 0 | ... CI16: =IF(CI15>0,$E15/$F15,0) -> 0
A17: 6 | B17: Старый Оскол №1 | C17: Проектирование, экспертиза, получение РНС | D17: 1 | E17: 2532.72 | F17: =COUNTA(K17:V17,X17:AI17,AK17:AV17,AX17:BI17,BK17:BV17,BX17:CI17) -> 23 | W17: =IF(K17="РНВ",$E17,IF(L17="РНВ",$E17,IF(M17="РНВ",$E17,IF(N17="РНВ",$E17,IF(O17="РНВ",$E17,IF(P17="РНВ",$E17,IF(Q17="РНВ",$E17,IF(R17="РНВ",$E17,IF(S17="РНВ",$E17,IF(T17="РНВ",$E17,IF(U17="РНВ",$E17,IF(V17="РНВ",$E17,0)))))))))))) -> 0 | AJ17: =IF(X17="РНВ",$E17,IF(Y17="РНВ",$E17,IF(Z17="РНВ",$E17,IF(AA17="РНВ",$E17,IF(AB17="РНВ",$E17,IF(AC17="РНВ",$E17,IF(AD17="РНВ",$E17,IF(AE17="РНВ",$E17,IF(AF17="РНВ",$E17,IF(AG17="РНВ",$E17,IF(AH17="РНВ",$E17,IF(AI17="РНВ",$E17,0)))))))))))) -> 0 | AT17: 1 | AU17: 1 | AV17: 1 | AW17: =IF(AK17="РНВ",$E17,IF(AL17="РНВ",$E17,IF(AM17="РНВ",$E17,IF(AN17="РНВ",$E17,IF(AO17="РНВ",$E17,IF(AP17="РНВ",$E17,IF(AQ17="РНВ",$E17,IF(AR17="РНВ",$E17,IF(AS17="РНВ",$E17,IF(AT17="РНВ",$E17,IF(AU17="РНВ",$E17,IF(AV17="РНВ",$E17,0)))))))))))) -> 0 | AX17: 1 | AY17: 1 | AZ17: 1 | BA17: 1 | BB17: 1 | BC17: 1 | BD17: 1 | BE17: 1 | BF17: 1 | BG17: 1 | BH17: 1 | BI17: 1 | BJ17: =IF(AX17="РНВ",$E17,IF(AY17="РНВ",$E17,IF(AZ17="РНВ",$E17,IF(BA17="РНВ",$E17,IF(BB17="РНВ",$E17,IF(BC17="РНВ",$E17,IF(BD17="РНВ",$E17,IF(BE17="РНВ",$E17,IF(BF17="РНВ",$E17,IF(BG17="РНВ",$E17,IF(BH17="РНВ",$E17,IF(BI17="РНВ",$E17,0)))))))))))) -> 0 | BK17: 1 | BL17: 1 | BM17: 1 | BN17: 1 | BO17: 1 | BP17: 1 | BQ17: 1 | BR17: РНВ | BW17: =IF(BK17="РНВ",$E17,IF(BL17="РНВ",$E17,IF(BM17="РНВ",$E17,IF(BN17="РНВ",$E17,IF(BO17="РНВ",$E17,IF(BP17="РНВ",$E17,IF(BQ17="РНВ",$E17,IF(BR17="РНВ",$E17,IF(BS17="РНВ",$E17,IF(BT17="РНВ",$E17,IF(BU17="РНВ",$E17,IF(BV17="РНВ",$E17,0)))))))))))) -> 2532.72 | CJ17: =IF(BX17="РНВ",$E17,IF(BY17="РНВ",$E17,IF(BZ17="РНВ",$E17,IF(CA17="РНВ",$E17,IF(CB17="РНВ",$E17,IF(CC17="РНВ",$E17,IF(CD17="РНВ",$E17,IF(CE17="РНВ",$E17,IF(CF17="РНВ",$E17,IF(CG17="РНВ",$E17,IF(CH17="РНВ",$E17,IF(CI17="РНВ",$E17,0)))))))))))) -> 0
AK18: =IF(AK17>0,$E17/$F17,0) -> 0 | AL18: =IF(AL17>0,$E17/$F17,0) -> 0 | AM18: =IF(AM17>0,$E17/$F17,0) -> 0 | AN18: =IF(AN17>0,$E17/$F17,0) -> 0 | AO18: =IF(AO17>0,$E17/$F17,0) -> 0 | AP18: =IF(AP17>0,$E17/$F17,0) -> 0 | AQ18: =IF(AQ17>0,$E17/$F17,0) -> 0 | AR18: =IF(AR17>0,$E17/$F17,0) -> 0 | ... AV18: =IF(AV17>0,$E17/$F17,0) -> 110.11826 | AX18: =IF(AX17>0,$E17/$F17,0) -> 110.11826 | AY18: =IF(AY17>0,$E17/$F17,0) -> 110.11826 | AZ18: =IF(AZ17>0,$E17/$F17,0) -> 110.11826 | BA18: =IF(BA17>0,$E17/$F17,0) -> 110.11826 | BB18: =IF(BB17>0,$E17/$F17,0) -> 110.11826 | BC18: =IF(BC17>0,$E17/$F17,0) -> 110.11826 | BD18: =IF(BD17>0,$E17/$F17,0) -> 110.11826 | BE18: =IF(BE17>0,$E17/$F17,0) -> 110.11826 | ... BI18: =IF(BI17>0,$E17/$F17,0) -> 110.11826 | BK18: =IF(BK17>0,$E17/$F17,0) -> 110.11826 | BL18: =IF(BL17>0,$E17/$F17,0) -> 110.11826 | BM18: =IF(BM17>0,$E17/$F17,0) -> 110.11826 | BN18: =IF(BN17>0,$E17/$F17,0) -> 110.11826 | BO18: =IF(BO17>0,$E17/$F17,0) -> 110.11826 | BP18: =IF(BP17>0,$E17/$F17,0) -> 110.11826 | BQ18: =IF(BQ17>0,$E17/$F17,0) -> 110.11826 | BR18: =IF(BR17>0,$E17/$F17,0) -> 110.11826 | ... BV18: =IF(BV17>0,$E17/$F17,0) -> 0 | BX18: =IF(BX17>0,$E17/$F17,0) -> 0 | BY18: =IF(BY17>0,$E17/$F17,0) -> 0 | BZ18: =IF(BZ17>0,$E17/$F17,0) -> 0 | CA18: =IF(CA17>0,$E17/$F17,0) -> 0 | CB18: =IF(CB17>0,$E17/$F17,0) -> 0 | CC18: =IF(CC17>0,$E17/$F17,0) -> 0 | CD18: =IF(CD17>0,$E17/$F17,0) -> 0 | CE18: =IF(CE17>0,$E17/$F17,0) -> 0 | ... CI18: =IF(CI17>0,$E17/$F17,0) -> 0
A19: 7 | B19: Старый Оскол №2 | C19: Проектирование, экспертиза, получение РНС | D19: 3 | E19: 9013.14 | F19: =COUNTA(K19:V19,X19:AI19,AK19:AV19,AX19:BI19,BK19:BV19,BX19:CI19) -> 20 | W19: =IF(K19="РНВ",$E19,IF(L19="РНВ",$E19,IF(M19="РНВ",$E19,IF(N19="РНВ",$E19,IF(O19="РНВ",$E19,IF(P19="РНВ",$E19,IF(Q19="РНВ",$E19,IF(R19="РНВ",$E19,IF(S19="РНВ",$E19,IF(T19="РНВ",$E19,IF(U19="РНВ",$E19,IF(V19="РНВ",$E19,0)))))))))))) -> 0 | AJ19: =IF(X19="РНВ",$E19,IF(Y19="РНВ",$E19,IF(Z19="РНВ",$E19,IF(AA19="РНВ",$E19,IF(AB19="РНВ",$E19,IF(AC19="РНВ",$E19,IF(AD19="РНВ",$E19,IF(AE19="РНВ",$E19,IF(AF19="РНВ",$E19,IF(AG19="РНВ",$E19,IF(AH19="РНВ",$E19,IF(AI19="РНВ",$E19,0)))))))))))) -> 0 | AW19: =IF(AK19="РНВ",$E19,IF(AL19="РНВ",$E19,IF(AM19="РНВ",$E19,IF(AN19="РНВ",$E19,IF(AO19="РНВ",$E19,IF(AP19="РНВ",$E19,IF(AQ19="РНВ",$E19,IF(AR19="РНВ",$E19,IF(AS19="РНВ",$E19,IF(AT19="РНВ",$E19,IF(AU19="РНВ",$E19,IF(AV19="РНВ",$E19,0)))))))))))) -> 0 | BB19: 1 | BC19: 1 | BD19: 1 | BE19: 1 | BF19: 1 | BG19: 1 | BH19: 1 | BI19: 1 | BJ19: =IF(AX19="РНВ",$E19,IF(AY19="РНВ",$E19,IF(AZ19="РНВ",$E19,IF(BA19="РНВ",$E19,IF(BB19="РНВ",$E19,IF(BC19="РНВ",$E19,IF(BD19="РНВ",$E19,IF(BE19="РНВ",$E19,IF(BF19="РНВ",$E19,IF(BG19="РНВ",$E19,IF(BH19="РНВ",$E19,IF(BI19="РНВ",$E19,0)))))))))))) -> 0 | BK19: 1 | BL19: 1 | BM19: 1 | BN19: 1 | BO19: 1 | BP19: 1 | BQ19: 1 | BR19: 1 | BS19: 1 | BT19: 1 | BU19: 1 | BV19: РНВ | BW19: =IF(BK19="РНВ",$E19,IF(BL19="РНВ",$E19,IF(BM19="РНВ",$E19,IF(BN19="РНВ",$E19,IF(BO19="РНВ",$E19,IF(BP19="РНВ",$E19,IF(BQ19="РНВ",$E19,IF(BR19="РНВ",$E19,IF(BS19="РНВ",$E19,IF(BT19="РНВ",$E19,IF(BU19="РНВ",$E19,IF(BV19="РНВ",$E19,0)))))))))))) -> 9013.14 | CJ19: =IF(BX19="РНВ",$E19,IF(BY19="РНВ",$E19,IF(BZ19="РНВ",$E19,IF(CA19="РНВ",$E19,IF(CB19="РНВ",$E19,IF(CC19="РНВ",$E19,IF(CD19="РНВ",$E19,IF(CE19="РНВ",$E19,IF(CF19="РНВ",$E19,IF(CG19="РНВ",$E19,IF(CH19="РНВ",$E19,IF(CI19="РНВ",$E19,0)))))))))))) -> 0
AK20: =IF(AK19>0,$E19/$F19,0) -> 0 | AL20: =IF(AL19>0,$E19/$F19,0) -> 0 | AM20: =IF(AM19>0,$E19/$F19,0) -> 0 | AN20: =IF(AN19>0,$E19/$F19,0) -> 0 | AO20: =IF(AO19>0,$E19/$F19,0) -> 0 | AP20: =IF(AP19>0,$E19/$F19,0) -> 0 | AQ20: =IF(AQ19>0,$E19/$F19,0) -> 0 | AR20: =IF(AR19>0,$E19/$F19,0) -> 0 | ... AV20: =IF(AV19>0,$E19/$F19,0) -> 0 | AX20: =IF(AX19>0,$E19/$F19,0) -> 0 | AY20: =IF(AY19>0,$E19/$F19,0) -> 0 | AZ20: =IF(AZ19>0,$E19/$F19,0) -> 0 | BA20: =IF(BA19>0,$E19/$F19,0) -> 0 | BB20: =IF(BB19>0,$E19/$F19,0) -> 450.657 | BC20: =IF(BC19>0,$E19/$F19,0) -> 450.657 | BD20: =IF(BD19>0,$E19/$F19,0) -> 450.657 | BE20: =IF(BE19>0,$E19/$F19,0) -> 450.657 | ... BI20: =IF(BI19>0,$E19/$F19,0) -> 450.657 | BK20: =IF(BK19>0,$E19/$F19,0) -> 450.657 | BL20: =IF(BL19>0,$E19/$F19,0) -> 450.657 | BM20: =IF(BM19>0,$E19/$F19,0) -> 450.657 | BN20: =IF(BN19>0,$E19/$F19,0) -> 450.657 | BO20: =IF(BO19>0,$E19/$F19,0) -> 450.657 | BP20: =IF(BP19>0,$E19/$F19,0) -> 450.657 | BQ20: =IF(BQ19>0,$E19/$F19,0) -> 450.657 | BR20: =IF(BR19>0,$E19/$F19,0) -> 450.657 | ... BV20: =IF(BV19>0,$E19/$F19,0) -> 450.657 | BX20: =IF(BX19>0,$E19/$F19,0) -> 0 | BY20: =IF(BY19>0,$E19/$F19,0) -> 0 | BZ20: =IF(BZ19>0,$E19/$F19,0) -> 0 | CA20: =IF(CA19>0,$E19/$F19,0) -> 0 | CB20: =IF(CB19>0,$E19/$F19,0) -> 0 | CC20: =IF(CC19>0,$E19/$F19,0) -> 0 | CD20: =IF(CD19>0,$E19/$F19,0) -> 0 | CE20: =IF(CE19>0,$E19/$F19,0) -> 0 | ... CI20: =IF(CI19>0,$E19/$F19,0) -> 0
A21: 8 | B21: Старый Оскол №3 | C21: Проектирование, экспертиза, получение РНС | D21: 2 | E21: 5404.72 | F21: =COUNTA(K21:V21,X21:AI21,AK21:AV21,AX21:BI21,BK21:BV21,BX21:CI21) -> 21 | W21: =IF(K21="РНВ",$E21,IF(L21="РНВ",$E21,IF(M21="РНВ",$E21,IF(N21="РНВ",$E21,IF(O21="РНВ",$E21,IF(P21="РНВ",$E21,IF(Q21="РНВ",$E21,IF(R21="РНВ",$E21,IF(S21="РНВ",$E21,IF(T21="РНВ",$E21,IF(U21="РНВ",$E21,IF(V21="РНВ",$E21,0)))))))))))) -> 0 | AJ21: =IF(X21="РНВ",$E21,IF(Y21="РНВ",$E21,IF(Z21="РНВ",$E21,IF(AA21="РНВ",$E21,IF(AB21="РНВ",$E21,IF(AC21="РНВ",$E21,IF(AD21="РНВ",$E21,IF(AE21="РНВ",$E21,IF(AF21="РНВ",$E21,IF(AG21="РНВ",$E21,IF(AH21="РНВ",$E21,IF(AI21="РНВ",$E21,0)))))))))))) -> 0 | AW21: =IF(AK21="РНВ",$E21,IF(AL21="РНВ",$E21,IF(AM21="РНВ",$E21,IF(AN21="РНВ",$E21,IF(AO21="РНВ",$E21,IF(AP21="РНВ",$E21,IF(AQ21="РНВ",$E21,IF(AR21="РНВ",$E21,IF(AS21="РНВ",$E21,IF(AT21="РНВ",$E21,IF(AU21="РНВ",$E21,IF(AV21="РНВ",$E21,0)))))))))))) -> 0 | BJ21: =IF(AX21="РНВ",$E21,IF(AY21="РНВ",$E21,IF(AZ21="РНВ",$E21,IF(BA21="РНВ",$E21,IF(BB21="РНВ",$E21,IF(BC21="РНВ",$E21,IF(BD21="РНВ",$E21,IF(BE21="РНВ",$E21,IF(BF21="РНВ",$E21,IF(BG21="РНВ",$E21,IF(BH21="РНВ",$E21,IF(BI21="РНВ",$E21,0)))))))))))) -> 0 | BK21: 1 | BL21: 1 | BM21: 1 | BN21: 1 | BO21: 1 | BP21: 1 | BQ21: 1 | BR21: 1 | BS21: 1 | BT21: 1 | BU21: 1 | BV21: 1 | BW21: =IF(BK21="РНВ",$E21,IF(BL21="РНВ",$E21,IF(BM21="РНВ",$E21,IF(BN21="РНВ",$E21,IF(BO21="РНВ",$E21,IF(BP21="РНВ",$E21,IF(BQ21="РНВ",$E21,IF(BR21="РНВ",$E21,IF(BS21="РНВ",$E21,IF(BT21="РНВ",$E21,IF(BU21="РНВ",$E21,IF(BV21="РНВ",$E21,0)))))))))))) -> 0 | BX21: 1 | BY21: 1 | BZ21: 1 | CA21: 1 | CB21: 1 | CC21: 1 | CD21: 1 | CE21: 1 | CF21: РНВ | CJ21: =IF(BX21="РНВ",$E21,IF(BY21="РНВ",$E21,IF(BZ21="РНВ",$E21,IF(CA21="РНВ",$E21,IF(CB21="РНВ",$E21,IF(CC21="РНВ",$E21,IF(CD21="РНВ",$E21,IF(CE21="РНВ",$E21,IF(CF21="РНВ",$E21,IF(CG21="РНВ",$E21,IF(CH21="РНВ",$E21,IF(CI21="РНВ",$E21,0)))))))))))) -> 5404.72
AK22: =IF(AK21>0,$E21/$F21,0) -> 0 | AL22: =IF(AL21>0,$E21/$F21,0) -> 0 | AM22: =IF(AM21>0,$E21/$F21,0) -> 0 | AN22: =IF(AN21>0,$E21/$F21,0) -> 0 | AO22: =IF(AO21>0,$E21/$F21,0) -> 0 | AP22: =IF(AP21>0,$E21/$F21,0) -> 0 | AQ22: =IF(AQ21>0,$E21/$F21,0) -> 0 | AR22: =IF(AR21>0,$E21/$F21,0) -> 0 | ... AV22: =IF(AV21>0,$E21/$F21,0) -> 0 | AX22: =IF(AX21>0,$E21/$F21,0) -> 0 | AY22: =IF(AY21>0,$E21/$F21,0) -> 0 | AZ22: =IF(AZ21>0,$E21/$F21,0) -> 0 | BA22: =IF(BA21>0,$E21/$F21,0) -> 0 | BB22: =IF(BB21>0,$E21/$F21,0) -> 0 | BC22: =IF(BC21>0,$E21/$F21,0) -> 0 | BD22: =IF(BD21>0,$E21/$F21,0) -> 0 | BE22: =IF(BE21>0,$E21/$F21,0) -> 0 | ... BI22: =IF(BI21>0,$E21/$F21,0) -> 0 | BK22: =IF(BK21>0,$E21/$F21,0) -> 257.36762 | BL22: =IF(BL21>0,$E21/$F21,0) -> 257.36762 | BM22: =IF(BM21>0,$E21/$F21,0) -> 257.36762 | BN22: =IF(BN21>0,$E21/$F21,0) -> 257.36762 | BO22: =IF(BO21>0,$E21/$F21,0) -> 257.36762 | BP22: =IF(BP21>0,$E21/$F21,0) -> 257.36762 | BQ22: =IF(BQ21>0,$E21/$F21,0) -> 257.36762 | BR22: =IF(BR21>0,$E21/$F21,0) -> 257.36762 | ... BV22: =IF(BV21>0,$E21/$F21,0) -> 257.36762 | BX22: =IF(BX21>0,$E21/$F21,0) -> 257.36762 | BY22: =IF(BY21>0,$E21/$F21,0) -> 257.36762 | BZ22: =IF(BZ21>0,$E21/$F21,0) -> 257.36762 | CA22: =IF(CA21>0,$E21/$F21,0) -> 257.36762 | CB22: =IF(CB21>0,$E21/$F21,0) -> 257.36762 | CC22: =IF(CC21>0,$E21/$F21,0) -> 257.36762 | CD22: =IF(CD21>0,$E21/$F21,0) -> 257.36762 | CE22: =IF(CE21>0,$E21/$F21,0) -> 257.36762 | ... CI22: =IF(CI21>0,$E21/$F21,0) -> 0
A23: 9 | B23: Павловск №3 | C23: Строительство | D23: 5 | E23: 13670.6 | F23: =COUNTA(K23:V23,X23:AI23,AK23:AV23,AX23:BI23,BK23:BV23,BX23:CI23) -> 31 | P23: 1 | Q23: 1 | R23: 1 | S23: 1 | T23: 1 | U23: 1 | V23: 1 | W23: =IF(K23="РНВ",$E23,IF(L23="РНВ",$E23,IF(M23="РНВ",$E23,IF(N23="РНВ",$E23,IF(O23="РНВ",$E23,IF(P23="РНВ",$E23,IF(Q23="РНВ",$E23,IF(R23="РНВ",$E23,IF(S23="РНВ",$E23,IF(T23="РНВ",$E23,IF(U23="РНВ",$E23,IF(V23="РНВ",$E23,0)))))))))))) -> 0 | X23: 1 | Y23: 1 | Z23: 1 | AA23: 1 | AB23: 1 | AC23: 1 | AD23: 1 | AE23: 1 | AF23: 1 | AG23: 1 | AH23: 1 | AI23: 1 | AJ23: =IF(X23="РНВ",$E23,IF(Y23="РНВ",$E23,IF(Z23="РНВ",$E23,IF(AA23="РНВ",$E23,IF(AB23="РНВ",$E23,IF(AC23="РНВ",$E23,IF(AD23="РНВ",$E23,IF(AE23="РНВ",$E23,IF(AF23="РНВ",$E23,IF(AG23="РНВ",$E23,IF(AH23="РНВ",$E23,IF(AI23="РНВ",$E23,0)))))))))))) -> 0 | AK23: 1 | AL23: 1 | AM23: 1 | AN23: 1 | AO23: 1 | AP23: 1 | AQ23: 1 | AR23: 1 | AS23: 1 | AT23: 1 | AU23: 1 | AV23: РНВ | AW23: =IF(AK23="РНВ",$E23,IF(AL23="РНВ",$E23,IF(AM23="РНВ",$E23,IF(AN23="РНВ",$E23,IF(AO23="РНВ",$E23,IF(AP23="РНВ",$E23,IF(AQ23="РНВ",$E23,IF(AR23="РНВ",$E23,IF(AS23="РНВ",$E23,IF(AT23="РНВ",$E23,IF(AU23="РНВ",$E23,IF(AV23="РНВ",$E23,0)))))))))))) -> 13670.6 | BJ23: =IF(AX23="РНВ",$E23,IF(AY23="РНВ",$E23,IF(AZ23="РНВ",$E23,IF(BA23="РНВ",$E23,IF(BB23="РНВ",$E23,IF(BC23="РНВ",$E23,IF(BD23="РНВ",$E23,IF(BE23="РНВ",$E23,IF(BF23="РНВ",$E23,IF(BG23="РНВ",$E23,IF(BH23="РНВ",$E23,IF(BI23="РНВ",$E23,0)))))))))))) -> 0 | BW23: =IF(BK23="РНВ",$E23,IF(BL23="РНВ",$E23,IF(BM23="РНВ",$E23,IF(BN23="РНВ",$E23,IF(BO23="РНВ",$E23,IF(BP23="РНВ",$E23,IF(BQ23="РНВ",$E23,IF(BR23="РНВ",$E23,IF(BS23="РНВ",$E23,IF(BT23="РНВ",$E23,IF(BU23="РНВ",$E23,IF(BV23="РНВ",$E23,0)))))))))))) -> 0 | CJ23: =IF(BX23="РНВ",$E23,IF(BY23="РНВ",$E23,IF(BZ23="РНВ",$E23,IF(CA23="РНВ",$E23,IF(CB23="РНВ",$E23,IF(CC23="РНВ",$E23,IF(CD23="РНВ",$E23,IF(CE23="РНВ",$E23,IF(CF23="РНВ",$E23,IF(CG23="РНВ",$E23,IF(CH23="РНВ",$E23,IF(CI23="РНВ",$E23,0)))))))))))) -> 0
AK24: =IF(AK23>0,$E23/$F23,0) -> 440.9871 | AL24: =IF(AL23>0,$E23/$F23,0) -> 440.9871 | AM24: =IF(AM23>0,$E23/$F23,0) -> 440.9871 | AN24: =IF(AN23>0,$E23/$F23,0) -> 440.9871 | AO24: =IF(AO23>0,$E23/$F23,0) -> 440.9871 | AP24: =IF(AP23>0,$E23/$F23,0) -> 440.9871 | AQ24: =IF(AQ23>0,$E23/$F23,0) -> 440.9871 | AR24: =IF(AR23>0,$E23/$F23,0) -> 440.9871 | ... AV24: =IF(AV23>0,$E23/$F23,0) -> 440.9871 | AX24: =IF(AX23>0,$E23/$F23,0) -> 0 | AY24: =IF(AY23>0,$E23/$F23,0) -> 0 | AZ24: =IF(AZ23>0,$E23/$F23,0) -> 0 | BA24: =IF(BA23>0,$E23/$F23,0) -> 0 | BB24: =IF(BB23>0,$E23/$F23,0) -> 0 | BC24: =IF(BC23>0,$E23/$F23,0) -> 0 | BD24: =IF(BD23>0,$E23/$F23,0) -> 0 | BE24: =IF(BE23>0,$E23/$F23,0) -> 0 | ... BI24: =IF(BI23>0,$E23/$F23,0) -> 0 | BK24: =IF(BK23>0,$E23/$F23,0) -> 0 | BL24: =IF(BL23>0,$E23/$F23,0) -> 0 | BM24: =IF(BM23>0,$E23/$F23,0) -> 0 | BN24: =IF(BN23>0,$E23/$F23,0) -> 0 | BO24: =IF(BO23>0,$E23/$F23,0) -> 0 | BP24: =IF(BP23>0,$E23/$F23,0) -> 0 | BQ24: =IF(BQ23>0,$E23/$F23,0) -> 0 | BR24: =IF(BR23>0,$E23/$F23,0) -> 0 | ... BV24: =IF(BV23>0,$E23/$F23,0) -> 0 | BX24: =IF(BX23>0,$E23/$F23,0) -> 0 | BY24: =IF(BY23>0,$E23/$F23,0) -> 0 | BZ24: =IF(BZ23>0,$E23/$F23,0) -> 0 | CA24: =IF(CA23>0,$E23/$F23,0) -> 0 | CB24: =IF(CB23>0,$E23/$F23,0) -> 0 | CC24: =IF(CC23>0,$E23/$F23,0) -> 0 | CD24: =IF(CD23>0,$E23/$F23,0) -> 0 | CE24: =IF(CE23>0,$E23/$F23,0) -> 0 | ... CI24: =IF(CI23>0,$E23/$F23,0) -> 0
A25: 10 | B25: Павловск №4 | C25: Есть право на зу, ждет реализации | D25: 4 | E25: 10728.41 | F25: =COUNTA(K25:V25,X25:AI25,AK25:AV25,AX25:BI25,BK25:BV25,BX25:CI25) -> 0 | W25: =IF(K25="РНВ",$E25,IF(L25="РНВ",$E25,IF(M25="РНВ",$E25,IF(N25="РНВ",$E25,IF(O25="РНВ",$E25,IF(P25="РНВ",$E25,IF(Q25="РНВ",$E25,IF(R25="РНВ",$E25,IF(S25="РНВ",$E25,IF(T25="РНВ",$E25,IF(U25="РНВ",$E25,IF(V25="РНВ",$E25,0)))))))))))) -> 0 | AJ25: =IF(X25="РНВ",$E25,IF(Y25="РНВ",$E25,IF(Z25="РНВ",$E25,IF(AA25="РНВ",$E25,IF(AB25="РНВ",$E25,IF(AC25="РНВ",$E25,IF(AD25="РНВ",$E25,IF(AE25="РНВ",$E25,IF(AF25="РНВ",$E25,IF(AG25="РНВ",$E25,IF(AH25="РНВ",$E25,IF(AI25="РНВ",$E25,0)))))))))))) -> 0 | AW25: =IF(AK25="РНВ",$E25,IF(AL25="РНВ",$E25,IF(AM25="РНВ",$E25,IF(AN25="РНВ",$E25,IF(AO25="РНВ",$E25,IF(AP25="РНВ",$E25,IF(AQ25="РНВ",$E25,IF(AR25="РНВ",$E25,IF(AS25="РНВ",$E25,IF(AT25="РНВ",$E25,IF(AU25="РНВ",$E25,IF(AV25="РНВ",$E25,0)))))))))))) -> 0 | BJ25: =IF(AX25="РНВ",$E25,IF(AY25="РНВ",$E25,IF(AZ25="РНВ",$E25,IF(BA25="РНВ",$E25,IF(BB25="РНВ",$E25,IF(BC25="РНВ",$E25,IF(BD25="РНВ",$E25,IF(BE25="РНВ",$E25,IF(BF25="РНВ",$E25,IF(BG25="РНВ",$E25,IF(BH25="РНВ",$E25,IF(BI25="РНВ",$E25,0)))))))))))) -> 0 | BW25: =IF(BK25="РНВ",$E25,IF(BL25="РНВ",$E25,IF(BM25="РНВ",$E25,IF(BN25="РНВ",$E25,IF(BO25="РНВ",$E25,IF(BP25="РНВ",$E25,IF(BQ25="РНВ",$E25,IF(BR25="РНВ",$E25,IF(BS25="РНВ",$E25,IF(BT25="РНВ",$E25,IF(BU25="РНВ",$E25,IF(BV25="РНВ",$E25,0)))))))))))) -> 0 | CJ25: =IF(BX25="РНВ",$E25,IF(BY25="РНВ",$E25,IF(BZ25="РНВ",$E25,IF(CA25="РНВ",$E25,IF(CB25="РНВ",$E25,IF(CC25="РНВ",$E25,IF(CD25="РНВ",$E25,IF(CE25="РНВ",$E25,IF(CF25="РНВ",$E25,IF(CG25="РНВ",$E25,IF(CH25="РНВ",$E25,IF(CI25="РНВ",$E25,0)))))))))))) -> 0
AK26: =IF(AK25>0,$E25/$F25,0) -> 0 | AL26: =IF(AL25>0,$E25/$F25,0) -> 0 | AM26: =IF(AM25>0,$E25/$F25,0) -> 0 | AN26: =IF(AN25>0,$E25/$F25,0) -> 0 | AO26: =IF(AO25>0,$E25/$F25,0) -> 0 | AP26: =IF(AP25>0,$E25/$F25,0) -> 0 | AQ26: =IF(AQ25>0,$E25/$F25,0) -> 0 | AR26: =IF(AR25>0,$E25/$F25,0) -> 0 | ... AV26: =IF(AV25>0,$E25/$F25,0) -> 0 | AX26: =IF(AX25>0,$E25/$F25,0) -> 0 | AY26: =IF(AY25>0,$E25/$F25,0) -> 0 | AZ26: =IF(AZ25>0,$E25/$F25,0) -> 0 | BA26: =IF(BA25>0,$E25/$F25,0) -> 0 | BB26: =IF(BB25>0,$E25/$F25,0) -> 0 | BC26: =IF(BC25>0,$E25/$F25,0) -> 0 | BD26: =IF(BD25>0,$E25/$F25,0) -> 0 | BE26: =IF(BE25>0,$E25/$F25,0) -> 0 | ... BI26: =IF(BI25>0,$E25/$F25,0) -> 0 | BK26: =IF(BK25>0,$E25/$F25,0) -> 0 | BL26: =IF(BL25>0,$E25/$F25,0) -> 0 | BM26: =IF(BM25>0,$E25/$F25,0) -> 0 | BN26: =IF(BN25>0,$E25/$F25,0) -> 0 | BO26: =IF(BO25>0,$E25/$F25,0) -> 0 | BP26: =IF(BP25>0,$E25/$F25,0) -> 0 | BQ26: =IF(BQ25>0,$E25/$F25,0) -> 0 | BR26: =IF(BR25>0,$E25/$F25,0) -> 0 | ... BV26: =IF(BV25>0,$E25/$F25,0) -> 0 | BX26: =IF(BX25>0,$E25/$F25,0) -> 0 | BY26: =IF(BY25>0,$E25/$F25,0) -> 0 | BZ26: =IF(BZ25>0,$E25/$F25,0) -> 0 | CA26: =IF(CA25>0,$E25/$F25,0) -> 0 | CB26: =IF(CB25>0,$E25/$F25,0) -> 0 | CC26: =IF(CC25>0,$E25/$F25,0) -> 0 | CD26: =IF(CD25>0,$E25/$F25,0) -> 0 | CE26: =IF(CE25>0,$E25/$F25,0) -> 0 | ... CI26: =IF(CI25>0,$E25/$F25,0) -> 0
